File: COPDIRMN_FC_300K_00005.csv
,Averaging Time (sec),Bridge 1 Excitation (,Bridge 1 Resistance (ohms),Center Position (mm),"Coil Signal"" (mV)",Coil Signal' (mV),Comment,Frequency (Hz),M. Quad. Signal (emu),"M. Raw"" (emu)",M. Raw' (emu),M. Std. Err. (emu),Magnetic Field (Oe),Mass (grams),Max. Field (Oe),Max. Temperature (K),Measure Status (code),Min. Field (Oe),Min. Temperature (K),Moment (emu),Motor Lag (deg),Motor Status (code),PPMS Status (code),Peak Amplitude (mm),Pressure (Torr),Range (mV),Sample Position (deg),System Field (Oe),System Temp. (K),Temperature (K),Time Stamp (sec),Transport Action,VSM Status (code)
0,0.999253354069792,,,6.44000299274921,0.000707195053151434,0.0042640503312993,,40.0298881530762,-2.37352675740343E-6,-2.11494715419086E-6,0.000389433144963235,4.42526772299281E-7,5999.8525,56.1084216244675,5999.902,300.0202026,0,5999.803,300.0194702,0.000389443496231023,20.1302406654066,0,5953,2.00233364533553,9.2E-6,0.25,,5999.8525,299.89845,300.0198364,29477220.095,1,0
8,0.999253354069792,,,6.44000299274921,0.000706689973947587,0.00425115535493153,,40.0298881530762,-2.22141444628263E-6,-1.963582769987E-6,0.000388299864402287,4.37384714694439E-7,5818.0665,56.1725151630444,5831.249,300.019165,0,5804.884,300.019104,0.000388310272388821,20.129280155094,0,5985,2.00222916552346,9.25E-6,0.25,,5818.0665,299.8968,300.0191345,29477239.025,1,0
16,0.999253354069792,,,6.44000299274921,0.000708900045532791,0.0042594585155659,,40.0298881530762,-2.15174737401522E-6,-1.89344011962393E-6,0.00038901247023876,4.21615220789737E-7,5607.945,55.8387597853328,5620.88,300.0198669,0,5595.01,300.0193481,0.000389022953625897,20.1305031333006,0,5985,2.0025410410265,9.25E-6,0.25,,5607.945,299.90055,300.0196075,29477247.065,1,0
24,0.999253354069792,,,6.44000299274921,0.000699890993553851,0.00425473595313153,,40.0298881530762,-2.87978560063056E-6,-2.62178374239919E-6,0.000388495994777233,4.72397763298063E-7,5328.53,55.7504357626598,5342.004,300.0209656,0,5315.056,300.0204468,0.000388505996460652,20.1283791735427,0,5985,2.00232719533164,9.2E-6,0.25,,5328.53,299.89635,300.0207062,29477258.025,1,0
32,0.999253354069792,,,6.44000299274921,0.000702420238334493,0.0042601017520453,,40.0298881530762,-2.73757073277227E-6,-2.47918577096077E-6,0.000389061279311295,3.73133974122622E-7,5127.639,56.0247873729098,5140.063,300.0220032,0,5115.215,300.0217896,0.000389071411250932,20.1178093145155,0,5985,2.0020589325582,9.2E-6,0.25,,5127.639,299.89235,300.0218964,29477265.99,1,0
40,0.999253354069792,,,6.44000299274921,0.000700331987637931,0.00424794541602601,,40.0298881530762,-2.73672310323446E-6,-2.47911005396259E-6,0.000387879320365052,3.74519771888009E-7,4931.4095,56.1732967915636,4946.079,300.0222778,0,4916.74,300.0213013,0.000387889416065121,20.1270730048929,0,5985,2.00243615899149,9.2E-6,0.25,,4931.4095,299.88725,300.02178955,29477274.095,1,0
48,0.999253354069792,,,6.44000299274921,0.000704206950612293,0.00423201791949801,,40.0298881530762,-2.14908298974252E-6,-1.89239993202705E-6,0.000386495192559161,3.84690793789578E-7,4665.537,56.3022654972367,4676.012,300.0215454,0,4655.062,300.020874,0.000386505628012526,20.1296178676836,0,5985,2.00259064297748,9.25E-6,0.25,,4665.537,299.8906,300.0212097,29477284.995,1,0
56,0.999253354069792,,,6.44000299274921,0.000708943277431335,0.0042249865460993,,40.0298881530762,-1.62109222742053E-6,-1.36478961989629E-6,0.000385936931979657,5.09900629666126E-7,4475.872,56.3984058051021,4487.747,300.0219116,0,4463.997,300.0216675,0.00038594770985569,20.1302626756861,0,5985,2.00262302719609,9.2E-6,0.25,,4475.872,299.89165,300.02178955,29477292.975,1,0
64,0.999253354069792,,,6.44000299274921,0.000709189958078364,0.00422270039598133,,40.0298881530762,-1.56427278527845E-6,-1.30808412534332E-6,0.000385737071112889,4.09675226661276E-7,4282.7565,56.3061736398329,4296.848,300.0226746,0,4268.665,300.0220032,0.00038574789035093,20.126907370064,0,5985,2.00262638575487,9.2E-6,0.25,,4282.7565,299.87865,300.0223389,29477301.055,1,0
72,0.999253354069792,,,6.44000299274921,0.000696326998306436,0.00420401437650676,,40.0298881530762,-2.4205889139536E-6,-2.16560659061522E-6,0.000383853070386069,4.65284484680134E-7,4028.9675,56.2256659023521,4041.326,300.022522,0,4016.609,300.0222473,0.000383863265324297,20.1287312660887,0,5985,2.00278344314782,9.2E-6,0.25,,4028.9675,299.8694,300.02238465,29477311.95,1,0
80,0.999253354069792,,,6.44000299274921,0.00069587373447259,0.00419131271274757,,40.0298881530762,-2.26692976499764E-6,-2.01267710605525E-6,0.000382748676948086,4.1865053405588E-7,3842.6225,56.2420801012559,3854.858,300.0206299,0,3830.387,300.0197754,0.000382758909113363,20.127634013769,0,5985,2.00261944253851,9.25E-6,0.25,,3842.6225,299.86765,300.02020265,29477319.96,1,0
88,0.999253354069792,,,6.45000260323286,0.000690539766758666,0.00417837619451215,,40.0298881530762,-2.54259692172345E-6,-2.28916778616581E-6,0.000381485097777436,4.32705293344145E-7,3658.58,56.3249327242944,3669.943,300.0206604,0,3647.217,300.0204468,0.000381495113790593,20.1313483302498,0,5985,2.0028030084412,9.25E-6,0.25,,3658.58,299.86705,300.0205536,29477327.995,1,0
96,0.999253354069792,,,6.44000299274921,0.000694322516320762,0.00416107278557851,,40.0298881530762,-1.9423369595427E-6,-1.68990697774651E-6,0.000379997476263151,5.08418091030562E-7,3409.658,56.1365602511598,3421.656,300.0180359,0,3397.66,300.0175171,0.000380007805982696,20.1355313709145,0,5985,2.00285179013785,9.25E-6,0.25,,3409.658,299.86875,300.0177765,29477338.94,1,0
104,0.999253354069792,,,6.44000299274921,0.000693505398748669,0.00413507139667449,,40.0298881530762,-1.61771027839404E-6,-1.36679734539408E-6,0.000377703642978459,4.56821498761607E-7,3230.389,55.9184858942944,3240.116,300.0185242,0,3220.662,300.0178833,0.000377714125642498,20.1351236958921,0,5985,2.00270296293109,9.25E-6,0.25,,3230.389,299.8588,300.01820375,29477346.94,1,0
112,0.999253354069792,,,6.44000299274921,0.000682067115036744,0.0041240971600168,,40.0298881530762,-2.46569508285864E-6,-2.21550201628298E-6,0.00037658230943513,4.38065079873445E-7,3052.8685,56.2960124690829,3064.007,300.0183105,0,3041.73,300.0179138,0.000376592193211902,20.1323520486292,0,5985,2.00255317541801,9.2E-6,0.25,,3052.8685,299.86565,300.01811215,29477354.96,1,0
120,0.999253354069792,,,6.44000299274921,0.00067571593722529,0.0040870307689621,,40.0298881530762,-2.46276323172986E-6,-2.21485458885603E-6,0.00037313503092575,4.24528817278063E-7,2809.258,56.2123782175252,2821.002,300.016571,0,2797.514,300.0158386,0.000373144784724719,20.1384592637971,0,5985,2.00288309804035,9.25E-6,0.25,,2809.258,299.86845,300.0162048,29477365.91,1,0
128,0.999253354069792,,,6.44000299274921,0.000669808096202509,0.00407124376641919,,40.0298881530762,-2.74612140202914E-6,-2.49917853216261E-6,0.000371658702812502,4.21223595642655E-7,2630.9245,56.4343607169867,2642.715,300.0167236,0,2619.134,300.0164185,0.00037166822900659,20.134151023474,0,5985,2.00279829414644,9.2E-6,0.25,,2630.9245,299.8681,300.01657105,29477373.915,1,0
136,0.999253354069792,,,6.44000299274921,0.000672419824237723,0.00403519158185491,,40.0298881530762,-1.96337756085771E-6,-1.71855247051145E-6,0.000368497606988719,3.7512329124946E-7,2453.4895,56.3319673809675,2465.26,300.0158691,0,2441.719,300.0152283,0.000368507542773231,20.1367535046938,0,5985,2.00279812864161,9.2E-6,0.25,,2453.4895,299.86835,300.0155487,29477381.925,1,0
144,0.999253354069792,,,6.44000299274921,0.000662666546525979,0.00400212413606297,,40.0298881530762,-2.32396846594285E-6,-2.08117193014899E-6,0.000365412144339029,3.79687672640859E-7,2214.0005,56.2209761312367,2225.649,300.015686,0,2202.352,300.0156555,0.000365421749025107,20.1364918044348,0,5985,2.00280455109275,9.2E-6,0.25,,2214.0005,299.86575,300.01567075,29477392.91,1,0
152,0.999253354069792,,,6.44000299274921,0.000655664513381351,0.00396963327686743,,40.0298881530762,-2.44922376031809E-6,-2.20839219228065E-6,0.000362435121595995,3.82785025949176E-7,2040.1805,56.1006053392752,2049.594,300.014679,0,2030.767,300.0136719,0.000362444532503869,20.1360232539558,0,5985,2.00272299857325,9.3E-6,0.25,,2040.1805,299.862,300.01417545,29477400.92,1,0
160,0.999253354069792,,,6.44000299274921,0.000651393538471517,0.00393595290659256,,40.0298881530762,-2.31364115457295E-6,-2.07484485287888E-6,0.000359363216225333,4.15303011519069E-7,1866.6935,56.4030955762175,1878.294,300.0135193,0,1855.093,300.01297,0.000359372611789604,20.1388413130198,0,5985,2.002818287837,9.2E-6,0.25,,1866.6935,299.85745,300.01324465,29477408.905,1,0
168,0.999253354069792,,,6.44000299274921,0.000643821309195891,0.00387258255143173,,40.0298881530762,-2.01783107891766E-6,-1.78282278207056E-6,0.000353667106513424,4.05588974363719E-7,1624.786,56.4851665707367,1636.369,300.0155029,0,1613.203,300.0145264,0.000353676549366882,20.1322259831607,0,5985,2.00255168715377,9.25E-6,0.25,,1624.786,299.8599,300.01501465,29477419.895,1,0
176,0.999253354069792,,,6.45000260323286,0.000631440792180354,0.00381528934189288,,40.0298881530762,-2.2410287987097E-6,-2.00956437025726E-6,0.000348316272487685,3.82534333075144E-7,1454.2535,56.2530229005252,1465.789,300.0161438,0,1442.718,300.0141296,0.000348325405868289,20.1412708478886,0,5985,2.00299888266866,9.25E-6,0.25,,1454.2535,299.8606,300.0151367,29477427.87,1,0
184,0.999253354069792,,,6.44000299274921,0.000618845776257946,0.00376143400373088,,40.0298881530762,-2.53650971675289E-6,-2.30830861675759E-6,0.000343381330905009,3.00113209194011E-7,1279.381,56.1006053392752,1290.87,300.0160217,0,1267.892,300.0158997,0.000343390128702373,20.1401904481045,0,5985,2.00277019166696,9.2E-6,0.25,,1279.381,299.85895,300.0159607,29477435.875,1,0
192,0.999253354069792,,,6.44000299274921,0.000604946889654087,0.00365761000109521,,40.0298881530762,-2.18400459989492E-6,-1.96206445111651E-6,0.000333959124632396,4.37674328447526E-7,1042.253,56.0599606562752,1053.769,300.0149536,0,1030.737,300.0149536,0.000333967857035241,20.1394120273343,0,5985,2.00272389874456,9.25E-6,0.25,,1042.253,299.85505,300.0149536,29477446.87,1,0
200,0.999253354069792,,,6.44000299274921,0.000584892524361311,0.00357853654438083,,40.0298881530762,-2.75599547856628E-6,-2.53891086540556E-6,0.000326616770555337,3.78031816376769E-7,869.5195,56.1639172493329,878.885,300.0149841,0,860.154,300.0149536,0.000326624899677529,20.1418724680537,0,5985,2.00282781623076,9.25E-6,0.25,,869.5195,299.85355,300.01496885,29477454.865,1,0
208,0.999253354069792,,,6.44000299274921,0.000574948262237163,0.00347048829689729,,40.0298881530762,-1.98765832936164E-6,-1.77708133925604E-6,0.000316845632316182,3.86497461949621E-7,671.9995,56.313208296506,676.346,300.0163574,0,667.653,300.0162354,0.000316853990458729,20.1456706080443,0,5985,2.00300413056854,9.2E-6,0.25,,671.9995,299.85005,300.0162964,29477463.915,1,0
216,0.999253354069792,,,6.44000299274921,0.000540833178854609,0.00329788661709872,,40.0298881530762,-2.37881024211625E-6,-2.17874996803566E-6,0.000300998072465877,3.77532366830951E-7,459.2505,56.1553193356213,470.872,300.0160522,0,447.629,300.0138855,0.000301005671592383,20.1427696745044,0,5985,2.00304209941646,9.2E-6,0.25,,459.2505,299.85405,300.01496885,29477473.82,1,0
224,0.999253354069792,,,6.44000299274921,0.000493674980941867,0.00306367756069779,,40.0298881530762,-2.98642304817904E-6,-2.80063483736458E-6,0.000279478588573066,6.36866380525232E-7,282.2005,56.4898563418521,295.923,300.0168457,0,268.478,300.0157776,0.000279485142487839,20.1407333665608,0,5985,2.00311693354422,9.25E-6,0.25,,282.2005,299.8479,300.01631165,29477481.845,1,0
232,0.999253354069792,,,6.44000299274921,0.000196622647228038,0.00132940070351919,,40.0298881530762,-2.85784704061884E-6,-2.77735034303276E-6,0.00012101410551667,5.66815074469302E-7,72.458,56.7993812354675,76.747,300.0163574,0,68.169,300.0163574,0.00012101590411636,20.1386080656212,0,5985,2.00295166586781,9.25E-6,0.25,,72.458,299.8414,300.0163574,29477491.625,1,0
240,0.999253354069792,,,6.44000299274921,2.98354723595301E-5,0.00033214465648286,,40.0298881530762,-2.42607115815693E-6,-2.40610550054459E-6,2.99373470443574E-5,4.94960631949813E-7,-148.2825,56.6555615879291,-136.822,300.0162048,0,-159.743,300.0147705,2.99366487311852E-5,20.1439862974775,0,5985,2.0032212464038,9.2E-6,0.25,,-148.2825,299.8386,300.01548765,29477501.825,1,0
248,0.999253354069792,,,6.44000299274921,-5.6652193197426E-5,-0.000171623933310423,,40.0298881530762,-2.40655613190453E-6,-2.41717987893463E-6,-1.60972006418559E-5,5.60464748894735E-7,-320.1235,56.3210245816983,-309.476,300.0151672,0,-330.771,300.0148926,-1.60992907567552E-5,20.1440056017643,0,5985,2.00314048301666,9.2E-6,0.25,,-320.1235,299.8381,300.0150299,29477509.815,1,0
256,0.999253354069792,,,6.44000299274921,-0.000151698190633909,-0.000708294721679669,,40.0298881530762,-2.64396195075455E-6,-2.68719474106771E-6,-6.51845713701575E-5,4.08522468941805E-7,-547.689,56.4281076888329,-545.548,300.0140381,0,-549.83,300.0140381,-6.51883140355313E-5,20.1409272587119,0,5985,2.00311853084477,9.25E-6,0.25,,-547.689,299.8384,300.0140381,29477520.68,1,0
264,0.999253354069792,,,6.44000299274921,-0.000197109647923985,-0.0010210703309489,,40.0298881530762,-1.89642382519941E-6,-1.95859227061712E-6,-9.36486854259069E-5,3.82838322877897E-7,-719.8285,56.3077368968713,-710.87,300.0137329,0,-728.787,300.013031,-9.36527962398537E-5,20.1378223886624,0,5985,2.00294883143967,9.25E-6,0.25,,-719.8285,299.8338,300.01338195,29477528.8,1,0
272,0.999253354069792,,,6.44000299274921,-0.000250330395803515,-0.00131502807274097,,40.0298881530762,-2.12934295305126E-6,-2.20937805357708E-6,-0.000120550817178226,3.6641101240613E-7,-884.776,56.6344576179098,-874.423,300.0127563,0,-895.129,300.0118713,-0.000120555896621527,20.1453329277208,0,5985,2.00303319501931,9.2E-6,0.25,,-884.776,299.8348,300.0123138,29477536.775,1,0
280,0.999253354069792,,,6.44000299274921,-0.000307235185490991,-0.00163027893714948,,40.0298881530762,-2.36393800217856E-6,-2.46312870377874E-6,-0.000149396985922408,4.00184144206188E-7,-1108.386,56.1545377071021,-1103.574,300.0128784,0,-1113.198,300.0123901,-0.000149403099528408,20.1427019865196,0,5985,2.00311830550583,9.2E-6,0.25,,-1108.386,299.8386,300.01263425,29477547.63,1,0
288,0.999253354069792,,,6.44000299274921,-0.000352840878304006,-0.00188380426275042,,40.0298881530762,-2.5387658709479E-6,-2.65336575986965E-6,-0.000172600362343701,3.625064925062E-7,-1274.5635,56.3593243791406,-1263.758,300.0135193,0,-1285.369,300.0128784,-0.00017260730114856,20.141766989231,0,5985,2.00307431833523,9.2E-6,0.25,,-1274.5635,299.83865,300.01319885,29477555.78,1,0
296,0.999253354069792,,,6.44000299274921,-0.000384491880512141,-0.00209205302185178,,40.0298881530762,-2.16652868843481E-6,-2.29373621005813E-6,-0.000191562675681802,4.23103780434187E-7,-1434.462,56.343691808756,-1426.515,300.0120544,0,-1442.409,300.0097351,-0.000191569927248167,20.1430575793076,0,5985,2.00314153090947,9.25E-6,0.25,,-1434.462,299.83855,300.01089475,29477563.775,1,0
304,0.999253354069792,,,6.44000299274921,-0.000431802566973404,-0.00235374410430443,,40.0298881530762,-2.36805653204852E-6,-2.51117741185133E-6,-0.000215528372096109,3.7652145778594E-7,-1665.805,56.6336759893906,-1661.836,300.0126953,0,-1669.774,300.0119934,-0.000215536496196797,20.1421373114784,0,5985,2.00299297786647,9.25E-6,0.25,,-1665.805,299.83695,300.01234435,29477575.37,1,0
312,0.999253354069792,,,6.44000299274921,-0.00046722067939948,-0.00255853609819037,,40.0298881530762,-2.38296979850392E-6,-2.53851722413642E-6,-0.000234236021618955,3.54455644844167E-7,-1832.909,56.750138638756,-1825.027,300.0119324,0,-1840.791,300.0119019,-0.000234244720252143,20.142644313538,0,5985,2.00309991636904,9.2E-6,0.25,,-1832.909,299.83495,300.01191715,29477583.79,1,0
320,0.999253354069792,,,6.44000299274921,-0.000498454281382464,-0.00273520013983721,,40.0298881530762,-2.45609921421264E-6,-2.62236166573314E-6,-0.000250372360195026,3.55092737313331E-7,-1988.8865,56.7954730928714,-1979.112,300.0119629,0,-1998.661,300.0113525,-0.000250381594808468,20.1426807682191,0,5985,2.00328043489582,9.2E-6,0.25,,-1988.8865,299.835,300.0116577,29477591.775,1,0
328,0.999253354069792,,,6.44000299274921,-0.000533215138608447,-0.00297844806488001,,40.0298881530762,-1.82556302578278E-6,-2.0065620792234E-6,-0.000272529722956234,3.32375423986111E-7,-2233.1905,56.8337728903137,-2231.306,300.0125122,0,-2235.075,300.0125122,-0.000272539220067554,20.1417421121855,0,5985,2.00300035408392,9.2E-6,0.25,,-2233.1905,299.8307,300.0125122,29477604.355,1,0
336,0.999253354069792,,,6.44000299274921,-0.000568364634075009,-0.00316221771095445,,40.0298881530762,-2.13780567734599E-6,-2.32997165753285E-6,-0.000289358996156724,4.10320383899805E-7,-2376.078,56.6946430138906,-2365.896,300.0122986,0,-2386.26,300.0118103,-0.000289369206858908,20.1400269891483,0,5985,2.00314393688821,9.2E-6,0.25,,-2376.078,299.83155,300.01205445,29477611.75,1,0
344,0.999253354069792,,,6.44000299274921,-0.000607341160767306,-0.00336618851222161,,40.0298881530762,-2.48089145519348E-6,-2.68544094222101E-6,-0.000308015459303004,3.66735097071538E-7,-2528.34,56.3647957787752,-2520.093,300.0122375,0,-2536.587,300.0109558,-0.000308026459331974,20.147475476232,0,5985,2.00343488229559,9.25E-6,0.25,,-2528.34,299.8269,300.01159665,29477619.74,1,0
352,0.999253354069792,,,6.44000299274921,-0.000656153434589141,-0.00363923063232002,,40.0298881530762,-2.64217523676151E-6,-2.86331306168431E-6,-0.000333002440824205,3.56645830099249E-7,-2742.1215,56.7157469839098,-2736.43,300.013092,0,-2747.813,300.0119934,-0.000333014317939426,20.1458545333983,0,5985,2.00337409051446,9.25E-6,0.25,,-2742.1215,299.82695,300.0125427,29477631.035,1,0
360,0.999253354069792,,,6.44000299274921,-0.000683152168337259,-0.00380382587768214,,40.0298881530762,-2.52435376952685E-6,-2.75550193026831E-6,-0.000348069214510734,3.52401768101339E-7,-2887.9705,56.5594212800637,-2879.826,300.0125122,0,-2896.115,300.0115356,-0.00034808146427453,20.1429086521862,0,5985,2.00309670336396,9.25E-6,0.25,,-2887.9705,299.82445,300.0120239,29477638.71,1,0
368,0.999253354069792,,,6.44000299274921,-0.000707358825124571,-0.0039185289695947,,40.0298881530762,-2.92083243603614E-6,-3.15899292500124E-6,-0.000358648412703709,3.43012405708634E-7,-3037.27,56.739977468006,-3027.28,300.0120544,0,-3047.26,300.0118408,-0.000358661245809012,20.1400416835024,0,5985,2.0029322070048,9.25E-6,0.25,,-3037.27,299.82315,300.0119476,29477646.71,1,0
376,0.999253354069792,,,6.44000299274921,-0.00071693470587529,-0.00401334447395797,,40.0298881530762,-2.32176316590124E-6,-2.56557974869877E-6,-0.00036714465405048,3.81781340284108E-7,-3260.435,56.5523866233906,-3251.097,300.0122375,0,-3269.773,300.0112,-0.000367157343501131,20.1443900291919,0,5985,2.00331187968256,9.2E-6,0.25,,-3260.435,299.82145,300.01171875,29477658.665,1,0
384,0.999253354069792,,,6.44000299274921,-0.000729404074455692,-0.00407428534566715,,40.0298881530762,-2.49774601998974E-6,-2.74529442548778E-6,-0.000372776745469347,3.60888000251446E-7,-3410.6045,56.3663590358137,-3401.238,300.0114746,0,-3419.971,300.0105896,-0.00037278971272996,20.1413753194471,0,5985,2.0031275773961,9.2E-6,0.25,,-3410.6045,299.8205,300.0110321,29477666.705,1,0
392,0.999253354069792,,,6.44000299274921,-0.00073818038232138,-0.004125631367238,,40.0298881530762,-2.49209766339574E-6,-2.74273806656198E-6,-0.00037743705205046,3.90849012724135E-7,-3559.5705,56.5390989385637,-3552.079,300.0115356,0,-3567.062,300.0114746,-0.000377450163309912,20.1462088199531,0,5985,2.00329965464201,9.2E-6,0.25,,-3559.5705,299.81905,300.0115051,29477674.705,1,0
400,0.999253354069792,,,6.44000299274921,-0.000747615841463112,-0.00414630358221875,,40.0298881530762,-3.01380822166449E-6,-3.26574500168938E-6,-0.000379422384082546,3.58100599371412E-7,-3783.1035,56.8087607776983,-3773.017,300.0120544,0,-3793.19,300.0115662,-0.000379435905865087,20.1477028652247,0,5985,2.00326231385676,9.25E-6,0.25,,-3783.1035,299.8178,300.0118103,29477686.67,1,0
408,0.999253354069792,,,6.44000299274921,-0.000743109720303228,-0.00415919681904461,,40.0298881530762,-2.41692444828453E-6,-2.66959071858292E-6,-0.000380502929948048,3.78041962198777E-7,-3936.645,56.4922012274098,-3926.436,300.0132751,0,-3946.854,300.0123901,-0.000380516102192715,20.1445246742719,0,5985,2.00323691260929,9.2E-6,0.25,,-3936.645,299.81825,300.0128326,29477694.695,1,0
416,0.999253354069792,,,6.44000299274921,-0.00075262447568361,-0.0041712107581666,,40.0298881530762,-3.07765835638798E-6,-3.33108573431618E-6,-0.000381683632185241,3.25469985062309E-7,-4090.996,56.831428004756,-4080.836,300.01297,0,-4101.156,300.0126343,-0.00038169727842715,20.1483855646386,0,5985,2.00340300381844,9.2E-6,0.25,,-4090.996,299.81595,300.01280215,29477702.665,1,0
424,0.999253354069792,,,6.44000299274921,-0.000754619188277437,-0.00418713186946618,,40.0298881530762,-3.01184167811258E-6,-3.26625450691489E-6,-0.000383172050609999,3.62294426504398E-7,-4303.743,56.7087123272368,-4295.998,300.0110779,0,-4311.488,300.010437,-0.000383185668223688,20.1452833789865,0,5985,2.00315941006604,9.2E-6,0.25,,-4303.743,299.81345,300.01075745,29477713.695,1,0
432,0.999253354069792,,,6.44000299274921,-0.000755426519684745,-0.00419746478777525,,40.0298881530762,-2.92507364349853E-6,-3.18005044327116E-6,-0.000384026506020208,3.42828313385909E-7,-4456.6295,56.5852150211983,-4446.326,300.0123901,0,-4466.933,300.0111694,-0.000384040106162778,20.1471853028333,0,5985,2.00356550355473,9.2E-6,0.25,,-4456.6295,299.81375,300.01177975,29477721.695,1,0
440,0.999253354069792,,,6.44000299274921,-0.000750350230926552,-0.00420098479757883,,40.0298881530762,-2.42100367765436E-6,-2.67616857367594E-6,-0.000384291202335586,4.24200683164509E-7,-4608.6435,56.6156985334483,-4598.379,300.0123596,0,-4618.908,300.010498,-0.000384304470345383,20.1451543449487,0,5985,2.00340586892162,9.2E-6,0.25,,-4608.6435,299.81085,300.0114288,29477729.645,1,0
448,0.999253354069792,,,6.45000260323286,-0.000759212969563631,-0.00421382978869309,,40.0298881530762,-3.01137336014326E-6,-3.2673577251735E-6,-0.000385566087258419,4.68059672287282E-7,-4842.8015,56.249114757929,-4834.432,300.011322,0,-4851.171,300.0109558,-0.000385579780885422,20.1455730208038,0,5985,2.00340628721624,9.2E-6,0.25,,-4842.8015,299.81155,300.0111389,29477741.635,1,0
456,0.999253354069792,,,6.44000299274921,-0.000756278219854792,-0.004221271266618,,40.0298881530762,-2.63755934594119E-6,-2.89399254658289E-6,-0.000386228846590909,4.06224515272557E-7,-4996.6735,56.8580033744099,-4986.958,300.0121155,0,-5006.389,300.0114441,-0.000386242321172136,20.1437848736585,0,5985,2.00315390526617,9.2E-6,0.25,,-4996.6735,299.8081,300.0117798,29477749.63,1,0
464,0.999253354069792,,,6.44000299274921,-0.000764147638701934,-0.00421846648408068,,40.0298881530762,-3.3782436535778E-6,-3.63451126799217E-6,-0.00038602224636458,3.70134472949737E-7,-5153.214,56.5719273363714,-5143.479,300.0121155,0,-5162.949,300.012085,-0.0003860362106627,20.1474109217364,0,5985,2.00357030282523,9.2E-6,0.25,,-5153.214,299.8082,300.01210025,29477757.62,1,0
472,0.999253354069792,,,6.44000299274921,-0.000763748213507202,-0.00422805868756798,,40.0298881530762,-3.1961104405424E-6,-3.45292449633734E-6,-0.000386846219641777,4.11380306639911E-7,-5366.377,56.6321127323521,-5355.933,300.0124207,0,-5376.821,300.0119629,-0.000386860088723939,20.1468150036688,0,5985,2.0036845571296,9.2E-6,0.25,,-5366.377,299.8061,300.0121918,29477768.61,1,0
480,0.999253354069792,,,6.44000299274921,-0.000763865595197213,-0.00424279022193474,,40.0298881530762,-2.98190772189395E-6,-3.23962419201583E-6,-0.000388204912019663,5.09486280611739E-7,-5523.332,56.7524835243137,-5512.924,300.0105286,0,-5533.74,300.0103149,-0.000388218653480287,20.1448466805123,0,5985,2.00341944538724,9.25E-6,0.25,,-5523.332,299.8064,300.01042175,29477776.635,1,0
488,0.999253354069792,,,6.44000299274921,-0.000759571940364894,-0.00424172426148411,,40.0298881530762,-2.61685836008365E-6,-2.87444944273363E-6,-0.000388004689115721,5.29066379019744E-7,-5675.8505,56.8454973181022,-5666.078,300.0122681,0,-5685.623,300.0105591,-0.000388018196322631,20.146573089336,0,5985,2.00363510624563,9.2E-6,0.25,,-5675.8505,299.8036,300.0114136,29477784.6,1,0
496,0.999253354069792,,,6.44000299274921,-0.000760964452545885,-0.00423772989423793,,40.0298881530762,-2.80176158396513E-6,-3.05914701582996E-6,-0.000387714544130281,4.32546508562074E-7,-5893.4985,56.8181403199291,-5883.1,300.0108643,0,-5903.897,300.0100708,-0.000387728150722312,20.147298746327,0,5985,2.00340379081707,9.2E-6,0.25,,-5893.4985,299.80245,300.01046755,29477795.63,1,0
504,0.999253354069792,,,6.44000299274921,-0.000749772807772986,-0.00424301714528469,,40.0298881530762,-1.72794647675136E-6,-1.98559433846598E-6,-0.000388063602615871,4.64750148710163E-7,-5992.051,56.7055858131598,-5992.051,300.0097046,0,-5992.051,300.0097046,-0.000388076495360082,20.1415781564613,0,5985,2.00313576518768,9.3E-6,0.25,,-5992.051,299.8,300.0097046,29477827.58,1,0
512,0.999253354069792,,,6.44000299274921,-0.000762291925302597,-0.00424285857661424,,40.0298881530762,-2.8410988257718E-6,-3.09880447676415E-6,-0.000388174034776478,5.48895901279731E-7,-5809.0725,56.2710003564675,-5795.058,300.0106812,0,-5823.087,300.0095215,-0.000388187677619713,20.1427569227041,0,5985,2.00348901635085,9.2E-6,0.25,,-5809.0725,299.78985,300.01010135,29477834.575,1,0
520,0.999253354069792,,,6.44000299274921,-0.000756633144621291,-0.00423255922323148,,40.0298881530762,-2.4961394463888E-6,-2.75318703745443E-6,-0.000387161878152208,4.39023841610557E-7,-5504.6965,56.3851181202752,-5502.168,300.011261,0,-5507.225,300.0112305,-0.000387175278386092,20.1457599007482,0,5985,2.00355305822178,9.2E-6,0.25,,-5504.6965,299.7979,300.01124575,29477846.31,1,0
528,0.999253354069792,,,6.44000299274921,-0.000751098864768658,-0.00423941910287538,,40.0298881530762,-1.90047353138549E-6,-2.15792676626049E-6,-0.000387739546450137,4.77023712256255E-7,-5321.4395,56.6117903908521,-5307.994,300.0097046,0,-5334.885,300.0096741,-0.000387752546179086,20.141765711815,0,5985,2.00326882706339,9.2E-6,0.25,,-5321.4395,299.801,300.00968935,29477853.555,1,0
536,0.999253354069792,,,6.44000299274921,-0.000752230374331408,-0.00422308177519922,,40.0298881530762,-2.25003644033204E-6,-2.50648647027067E-6,-0.000386231102777895,4.54682285425218E-7,-5120.1915,56.7173102409483,-5107.019,300.0099487,0,-5133.364,300.009491,-0.000386244290312546,20.1485326406197,0,5985,2.00367485042185,9.2E-6,0.25,,-5120.1915,299.79985,300.00971985,29477861.55,1,0
544,0.999253354069792,,,6.44000299274921,-0.000752609112725112,-0.00420510200735474,,40.0298881530762,-2.55862520568278E-6,-2.81406078343699E-6,-0.000384697317285145,3.42250202478416E-7,-4829.203,56.5883415352752,-4829.203,300.010376,0,-4829.203,300.010376,-0.000384710674187932,20.1492012493409,0,5985,2.00337181902201,9.2E-6,0.25,,-4829.203,299.7976,300.010376,29477873.42,1,0
552,0.999253354069792,,,6.44000299274921,-0.000749565069458709,-0.00421067199599211,,40.0298881530762,-2.2035535678196E-6,-2.45933174746898E-6,-0.000385179379078212,4.56030848631278E-7,-4657.15,56.780622151006,-4644.308,300.0112,0,-4669.992,300.0111694,-0.000385192527674428,20.1443534995013,0,5985,2.00318849769575,9.25E-6,0.25,,-4657.15,299.79235,300.0111847,29477880.535,1,0
560,0.999253354069792,,,6.44000299274921,-0.000749985548992035,-0.0042060332374328,,40.0298881530762,-2.31152434759012E-6,-2.56701285438763E-6,-0.000384738546938048,5.57457488057154E-7,-4467.018,56.8025077495445,-4456.667,300.0119019,0,-4477.369,300.0112305,-0.000384751760044001,20.1482607602793,0,5985,2.00337994307931,9.25E-6,0.25,,-4467.018,299.79315,300.0115662,29477888.53,1,0
568,0.999253354069792,,,6.44000299274921,-0.000741002457996789,-0.00418742416987652,,40.0298881530762,-1.7985315060103E-6,-2.05286328511965E-6,-0.000382953935732051,5.05605778478471E-7,-4178.302,56.8290831191983,-4175.972,300.0116577,0,-4180.632,300.0116577,-0.000382966756514236,20.1421028480668,0,5985,2.00335923944284,9.2E-6,0.25,,-4178.302,299.7906,300.0116577,29477900.79,1,0
576,0.999253354069792,,,6.44000299274921,-0.000747379287491153,-0.00417669534278107,,40.0298881530762,-2.52846193741155E-6,-2.78221869702559E-6,-0.000382110535446853,4.59404090489602E-7,-4024.0185,56.381209977679,-4011.594,300.0126038,0,-4036.443,300.0112305,-0.000382123819932821,20.1473407454392,0,5985,2.00329474659961,9.25E-6,0.25,,-4024.0185,299.7892,300.01191715,29477907.525,1,0
584,0.999253354069792,,,6.44000299274921,-0.000743477436293454,-0.00416711460726178,,40.0298881530762,-2.32833393258196E-6,-2.58148630149442E-6,-0.000381173705026387,4.10907622488925E-7,-3837.861,56.5422254526406,-3825.559,300.013916,0,-3850.163,300.0131531,-0.000381186852596276,20.1439299692765,0,5985,2.00344209776551,9.2E-6,0.25,,-3837.861,299.7839,300.01353455,29477915.525,1,0
592,0.999253354069792,,,6.45000260323286,-0.000737023391956141,-0.00415022331307704,,40.0298881530762,-2.01367137778023E-6,-2.26579739411644E-6,-0.000379598536512644,5.18347772088415E-7,-3560.047,56.9033378285253,-3557.781,300.0113525,0,-3562.313,300.0113525,-0.00037961139678414,20.1446287926851,0,5985,2.00332027508669,9.3E-6,0.25,,-3560.047,299.7834,300.0113525,29477927.705,1,0
600,0.999253354069792,,,6.44000299274921,-0.000736908031288325,-0.00413953595416433,,40.0298881530762,-2.16615019464934E-6,-2.4175840529918E-6,-0.00037855364555911,4.31403044365527E-7,-3405.446,56.8103240347368,-3393.438,300.0119324,0,-3417.454,300.0115356,-0.000378566581508587,20.145413889364,0,5985,2.00383889025305,9.25E-6,0.25,,-3405.446,299.78225,300.011734,29477934.5,1,0
608,0.999253354069792,,,6.44000299274921,-0.000735599734115892,-0.00411504716303261,,40.0298881530762,-2.42406480798173E-6,-2.67404032819633E-6,-0.000376360754196299,4.70704191122468E-7,-3224.0625,56.421854660679,-3212.083,300.0110168,0,-3236.042,300.0101929,-0.00037637377942307,20.1468040644313,0,5985,2.00383806101825,9.2E-6,0.25,,-3224.0625,299.7824,300.01060485,29477942.5,1,0
616,0.999253354069792,,,6.44000299274921,-0.000738607514892425,-0.00409251370037689,,40.0298881530762,-3.03533908016139E-6,-3.28403565640081E-6,-0.000374438528422806,3.81871967625785E-7,-2951.9065,56.8533136032945,-2948.96,300.0109863,0,-2954.853,300.0109863,-0.000374451908492787,20.1447373610174,0,5985,2.00366247394499,9.2E-6,0.25,,-2951.9065,299.7751,300.0109863,29477954.715,1,0
624,0.999253354069792,,,6.44000299274921,-0.000719496296488343,-0.0040722554163773,,40.0298881530762,-1.64905530388404E-6,-1.89644190858029E-6,-0.000372401297330022,3.95618721480181E-7,-2782.78,56.8447156895829,-2771.7,300.0108948,0,-2793.86,300.0101929,-0.000372413688461258,20.1433109454342,0,5985,2.0033756221972,9.2E-6,0.25,,-2782.78,299.7787,300.01054385,29477962.465,1,0
632,0.999253354069792,,,6.45000260323286,-0.000715873683203589,-0.00404399670251654,,40.0298881530762,-1.75908409085773E-6,-2.00474896811796E-6,-0.000369809827372666,4.3980678331621E-7,-2604.881,56.7423223535637,-2593.849,300.0100708,0,-2615.913,300.0091858,-0.000369822200523956,20.1516788279455,0,5985,2.00353351099029,9.25E-6,0.25,,-2604.881,299.78125,300.0096283,29477970.46,1,0
640,0.999253354069792,,,6.44000299274921,-0.000726296608358583,-0.00400148790323708,,40.0298881530762,-3.33342049831987E-6,-3.57664530625156E-6,-0.000366199473530748,4.07026473158985E-7,-2357.5385,56.6774471864675,-2352.378,300.0109253,0,-2362.699,300.0103149,-0.00036621279767735,20.1503046013042,0,5985,2.00351168678632,9.25E-6,0.25,,-2357.5385,299.7833,300.0106201,29477981.715,1,0
648,0.999253354069792,,,6.44000299274921,-0.000712639064986409,-0.00397630830068535,,40.0298881530762,-2.50630705176726E-6,-2.74797397575668E-6,-0.000363805598442206,4.46428024304191E-7,-2187.8775,57.1198489283522,-2176.247,300.0112305,0,-2199.508,300.0098877,-0.00036381830032433,20.1448863147785,0,5985,2.00323342433811,9.2E-6,0.25,,-2187.8775,299.78045,300.0105591,29477989.445,1,0
656,0.999253354069792,,,6.44000299274921,-0.000707884115148842,-0.00393683943076265,,40.0298881530762,-2.68694766619573E-6,-2.92621542502651E-6,-0.000360192223414112,3.75653090354107E-7,-2012.781,56.6399290175445,-2001.843,300.0111084,0,-2023.719,300.0101929,-0.000360204937669645,20.1464234933398,0,5985,2.0034498302096,9.25E-6,0.25,,-2012.781,299.7784,300.01065065,29477997.44,1,0
664,0.999253354069792,,,6.44000299274921,-0.000690739632826649,-0.00389225409901198,,40.0298881530762,-1.8465204025274E-6,-2.08303074988449E-6,-0.000355989408064347,5.10918436656433E-7,-1767.2535,56.6547799594098,-1762.868,300.0118713,0,-1771.639,300.0115967,-0.000356001451904033,20.1441721667269,0,5985,2.00336051093508,9.2E-6,0.25,,-1767.2535,299.7751,300.011734,29478008.815,1,0
672,0.999253354069792,,,6.44000299274921,-0.000682666098085243,-0.00382806924808248,,40.0298881530762,-2.1102212030885E-6,-2.34283435716144E-6,-0.000350129291535522,4.32211732931819E-7,-1604.0635,56.7884384361983,-1592.425,300.0133667,0,-1615.702,300.0115662,-0.000350141342730157,20.1487609861973,0,5985,2.00359892559275,9.25E-6,0.25,,-1604.0635,299.7747,300.01246645,29478016.43,1,0
680,0.999253354069792,,,6.44000299274921,-0.000682945653951306,-0.00379462173891493,,40.0298881530762,-2.64603274019064E-6,-2.87667729322354E-6,-0.000347180609162001,4.24977907815651E-7,-1430.073,56.9494539111599,-1419.249,300.0134583,0,-1440.897,300.0128784,-0.000347192936652192,20.1479540176797,0,5985,2.00350590809421,9.2E-6,0.25,,-1430.073,299.7722,300.01316835,29478024.415,1,0
688,0.999253354069792,,,6.44000299274921,-0.000663116903644538,-0.00370670691031425,,40.0298881530762,-2.22901014093902E-6,-2.45427275642285E-6,-0.000339048456002705,4.54637143359007E-7,-1181.1695,56.3796467206406,-1176.822,300.0118713,0,-1185.517,300.0105896,-0.000339060234888862,20.150379203317,0,5985,2.00367518049463,9.2E-6,0.25,,-1181.1695,299.76855,300.01123045,29478035.86,1,0
696,0.999253354069792,,,6.44000299274921,-0.000653682796802897,-0.00363086042904402,,40.0298881530762,-2.5506361302746E-6,-2.77135467314469E-6,-0.00033221819241646,3.42680827354971E-7,-1018.191,56.5922496778714,-1006.676,300.0133362,0,-1029.706,300.0115967,-0.000332229993625707,20.1472595172958,0,5985,2.00339731955221,9.2E-6,0.25,,-1018.191,299.7674,300.01246645,29478043.41,1,0
704,0.999253354069792,,,6.44000299274921,-0.000640618553314957,-0.00354738114494904,,40.0298881530762,-2.66640151196128E-6,-2.88206592227101E-6,-0.000324612175379931,3.79185534126954E-7,-846.2925,56.9775925378522,-837.57,300.0126343,0,-855.015,300.0119934,-0.000324623820708971,20.1459584169263,0,5985,2.00338253383164,9.2E-6,0.25,,-846.2925,299.767,300.01231385,29478051.415,1,0
712,0.999253354069792,,,6.44000299274921,-0.000607619713605461,-0.00339606459451596,,40.0298881530762,-2.04926940029126E-6,-2.25570584717368E-6,-0.00031069089993975,3.41912810654936E-7,-601.5225,56.6868267286983,-595.006,300.013092,0,-608.039,300.0125427,-0.000310701718182934,20.1475367027295,0,5985,2.00330462511657,9.25E-6,0.25,,-601.5225,299.76605,300.01281735,29478062.655,1,0
720,0.999253354069792,,,6.44000299274921,-0.000582149658096862,-0.00323991457904656,,40.0298881530762,-2.17432360393672E-6,-2.37131201869649E-6,-0.000296473717242203,4.22140516683498E-7,-433.9835,56.5985027060252,-424.551,300.0115051,0,-443.416,300.0112,-0.000296484169944919,20.1474883952734,0,5985,2.00308928349064,9.25E-6,0.25,,-433.9835,299.7638,300.01135255,29478070.4,1,0
728,0.999253354069792,,,6.44000299274921,-0.000357896366412722,-0.00196113811928907,,40.0298881530762,-1.80597042751053E-6,-1.92525298302905E-6,-0.000179545091446377,7.07134758130586E-7,-261.567,56.7720242372945,-250.002,300.0118408,0,-273.132,300.0116882,-0.000179551749633559,20.1464070835376,0,5985,2.00304366980002,9.25E-6,0.25,,-261.567,299.7663,300.0117645,29478078.425,1,0
736,0.999253354069792,,,6.44000299274921,-0.000186812911799569,-0.000929926144766585,,40.0298881530762,-2.37484946377266E-6,-2.43153969239646E-6,-8.53961713319847E-5,4.34607480140617E-7,-14.279,56.5226847396598,-9.969,300.0122375,0,-18.589,300.0114441,-8.5400346149136E-5,20.146976055605,0,5985,2.00305071334932,9.25E-6,0.25,,-14.279,299.7625,300.0118408,29478089.82,1,0
744,0.999253354069792,,,6.44000299274921,-6.76189277425405E-5,-0.000230556844544146,,40.0298881530762,-2.47999846524627E-6,-2.49421413093575E-6,-2.14988365807816E-5,5.59486938109241E-7,147.261,56.912717370756,158.634,300.0126953,0,135.888,300.0114746,-2.15011388365012E-5,20.1492705171826,0,5985,2.00282465893621,9.25E-6,0.25,,147.261,299.7589,300.01208495,29478097.375,1,0
752,0.999253354069792,,,6.44000299274921,2.09953743090694E-5,0.000259080686528434,,40.0298881530762,-2.09451190125924E-6,-2.0789506035556E-6,2.33173013967816E-5,3.97361033069511E-7,319.312,56.5688008222944,330.573,300.0131226,0,308.051,300.011322,2.33166184614106E-5,20.1485432611679,0,5985,2.00321112830355,9.2E-6,0.25,,319.312,299.75835,300.0122223,29478105.4,1,0
760,0.999253354069792,,,6.45000260323286,0.000108991481747954,0.000783200684378859,,40.0298881530762,-2.29124188730613E-6,-2.24385976216097E-6,7.1183635159296E-5,4.33290818187235E-7,561.7165,56.6610329875637,570.145,300.0113525,0,553.288,300.0102234,7.11842735112839E-5,20.1469731664287,0,5985,2.00313232369131,9.2E-6,0.25,,561.7165,299.7563,300.01078795,29478116.865,1,0
768,0.999253354069792,,,6.44000299274921,0.000154751280765486,0.00109494965674165,,40.0298881530762,-2.9920604572733E-6,-2.92580777631151E-6,9.9545112178339E-5,3.41633603716809E-7,719.422,56.4773502855444,730.521,300.0106812,0,708.323,300.0100098,9.95461440784925E-5,20.1497843895124,0,5985,2.00331936550792,9.25E-6,0.25,,719.422,299.7575,300.0103455,29478124.34,1,0
776,0.999253354069792,,,6.44000299274921,0.000211656621829268,0.0013775997290791,,40.0298881530762,-2.25927224124955E-6,-2.17579380485798E-6,0.000125496196907273,4.49852679934064E-7,882.7405,56.9392927404099,893.718,300.0114441,0,871.763,300.0108337,0.000125498507014805,20.1472666672049,0,5985,2.00337760253684,9.25E-6,0.25,,882.7405,299.756,300.0111389,29478132.34,1,0
784,0.999253354069792,,,6.44000299274921,0.000267706512819865,0.00172748264371798,,40.0298881530762,-2.62962533016045E-6,-2.52492658272265E-6,0.000157409569902052,3.7375789672109E-7,1119.9415,56.8001628639868,1126.031,300.0111389,0,1113.852,300.0106812,0.000157412601665291,20.1482322472489,0,5985,2.00331240493467,9.2E-6,0.25,,1119.9415,299.75405,300.01091005,29478143.89,1,0
792,0.999253354069792,,,6.44000299274921,0.000312366928513759,0.0019421295312047,,40.0298881530762,-1.94499709301402E-6,-1.82719813992724E-6,0.000177155940363531,4.36436570554917E-7,1270.75,56.8157954343714,1281.669,300.0097351,0,1259.831,300.0097046,0.000177160018483994,20.1474605447749,0,5985,2.00314644786105,9.25E-6,0.25,,1270.75,299.75695,300.00971985,29478151.345,1,0
800,0.999253354069792,,,6.44000299274921,0.000347615185706417,0.00214970162147927,,40.0298881530762,-1.98765465967656E-6,-1.8572449948406E-6,0.000196132092019252,3.73156531161209E-7,1432.966,57.0409044479099,1443.687,300.0105286,0,1422.245,300.0103455,0.000196136722204561,20.1494885670949,0,5985,2.00300218139957,9.2E-6,0.25,,1432.966,299.757,300.01043705,29478159.335,1,0
808,0.999253354069792,,,6.44000299274921,0.000384174116655861,0.00241018942774522,,40.0298881530762,-2.721846432857E-6,-2.57570377362837E-6,0.000219775273854675,3.80065520349389E-7,1661.07,56.7345060683714,1669.004,300.0104065,0,1653.136,300.0103149,0.000219780132678001,20.1496461295538,0,5985,2.00336368579785,9.2E-6,0.25,,1661.07,299.7541,300.0103607,29478170.805,1,0
816,0.999253354069792,,,6.44000299274921,0.000416374152717252,0.00259765307039771,,40.0298881530762,-2.72795656920974E-6,-2.57041864290833E-6,0.000236925176976983,4.59047182861774E-7,1809.368,56.6704125297944,1819.795,300.0115051,0,1798.941,300.0105591,0.000236930557851607,20.1491442003984,0,5985,2.00318328278332,9.25E-6,0.25,,1809.368,299.75385,300.0110321,29478178.32,1,0
824,0.999253354069792,,,6.44000299274921,0.00044377696334686,0.00276163596511447,,40.0298881530762,-2.80093668054649E-6,-2.63344595434801E-6,0.000251901157112421,3.8512119056837E-7,1965.1725,56.9447641400445,1973.684,300.011322,0,1956.661,300.0107117,0.000251906943889962,20.1495303018551,0,5985,2.00316258573564,9.2E-6,0.25,,1965.1725,299.7522,300.01101685,29478186.295,1,0
832,0.999253354069792,,,6.44000299274921,0.000481006050546427,0.00299198541610659,,40.0298881530762,-3.01570428435778E-6,-2.83423928947592E-6,0.000272923497837686,3.79287331012675E-7,2183.519,57.0330881627176,2189.306,300.0109863,0,2177.732,300.0109863,0.000272929779608362,20.1471949676749,0,5985,2.00310253503693,9.25E-6,0.25,,2183.519,299.74945,300.0109863,29478197.56,1,0
840,0.999253354069792,,,6.44000299274921,0.000516854620272711,0.00317766777649124,,40.0298881530762,-2.6706357230253E-6,-2.47785734536273E-6,0.000289966634909878,4.29497588454642E-7,2330.252,56.6344576179098,2340.487,300.0109863,0,2320.017,300.0105591,0.000289973660880899,20.1489150746824,0,5985,2.00300041223703,9.2E-6,0.25,,2330.252,299.74795,300.0107727,29478205.275,1,0
848,0.999253354069792,,,6.44000299274921,0.000549614055915136,0.00337141753599322,,40.0298881530762,-2.72286643716891E-6,-2.51832898045091E-6,0.000307662036124813,3.92763501601855E-7,2484.312,56.8431524325445,2494.416,300.0110779,0,2474.208,300.0108643,0.000307669566598383,20.1498625734073,0,5985,2.00302399447048,9.25E-6,0.25,,2484.312,299.7454,300.0109711,29478213.275,1,0
856,0.999253354069792,,,6.44000299274921,0.000600395162840059,0.00365234401503391,,40.0298881530762,-2.50735825146444E-6,-2.28574401622774E-6,0.000333378184640799,3.34674846559584E-7,2699.9025,56.9932251082368,2705.567,300.0103149,0,2694.238,300.0099182,0.00033338662772232,20.1480131022236,0,5985,2.0029986203762,9.2E-6,0.25,,2699.9025,299.74535,300.01011655,29478224.61,1,0
864,0.999253354069792,,,6.44000299274921,0.000627641369005499,0.00381833969798207,,40.0298881530762,-2.62498509142926E-6,-2.39330041831907E-6,0.000348531271700852,4.12381658321958E-7,2844.3995,56.9900985941599,2853.888,300.0107117,0,2834.911,300.0099792,0.000348540098903834,20.1499731725754,0,5985,2.00298681091036,9.2E-6,0.25,,2844.3995,299.74345,300.01034545,29478232.29,1,0
872,0.999253354069792,,,6.44000299274921,0.000641588607298936,0.00392807885336318,,40.0298881530762,-3.06345021739017E-6,-2.82515147496136E-6,0.000358468831976369,3.45139151129503E-7,2993.0915,56.8337728903137,3001.19,300.0110168,0,2984.993,300.0102844,0.000358477673142678,20.1498673885193,0,5985,2.00308513419523,9.2E-6,0.25,,2993.0915,299.7413,300.0106506,29478240.26,1,0
880,0.999253354069792,,,6.44000299274921,0.000660211017806056,0.00402417273262601,,40.0298881530762,-2.87858254271816E-6,-2.6344397096524E-6,0.000367284644908108,4.11759745454155E-7,3208.587,56.8806706014676,3216.031,300.011322,0,3201.143,300.0096436,0.000367293873377987,20.1491663490271,0,5985,2.00307423659108,9.2E-6,0.25,,3208.587,299.7427,300.0104828,29478251.76,1,0
888,0.999253354069792,,,6.44000299274921,0.000677682748198444,0.00408747495829863,,40.0298881530762,-2.29504425607087E-6,-2.04700601215947E-6,0.000373205515122506,3.98509364018642E-7,3347.248,56.8689461736791,3354.654,300.0113525,0,3339.842,300.0109558,0.000373215318613436,20.1516209008339,0,5985,2.002876902386,9.2E-6,0.25,,3347.248,299.7598,300.01115415,29478259.275,1,0
896,0.999253354069792,,,6.44000299274921,0.000681537611754602,0.00413256512702217,,40.0298881530762,-2.6416455560201E-6,-2.39090597195022E-6,0.000377244396129972,3.58378045816697E-7,3494.886,56.966649738583,3504.811,300.0120544,0,3484.961,300.0103149,0.000377254092977099,20.1497605845275,0,5985,2.0030032580692,9.2E-6,0.25,,3494.886,299.7471,300.01118465,29478267.235,1,0
904,0.999253354069792,,,6.44000299274921,0.000682297170696134,0.00416434221064892,,40.0298881530762,-3.05959175926942E-6,-2.80696507845509E-6,0.000380058436872269,4.21538371775006E-7,3709.851,56.5750538504483,3717.417,300.0110168,0,3702.285,300.0104675,0.000380067935480079,20.1498458069988,0,5985,2.00310466640754,9.25E-6,0.25,,3709.851,299.73455,300.01074215,29478278.6,1,0
912,0.999253354069792,,,6.44000299274921,0.00068372506317405,0.00416705357288327,,40.0298881530762,-2.97438963841842E-6,-2.72158362593927E-6,0.000380336443141062,5.21519077841715E-7,3853.039,56.9322580837368,3862.574,300.0115051,0,3843.504,300.0114136,0.000380346016871652,20.1495858855844,0,5985,2.00301955633184,9.25E-6,0.25,,3853.039,299.7323,300.01145935,29478286.25,1,0
920,0.999253354069792,,,6.44000299274921,0.000688653154527733,0.00418343850882624,,40.0298881530762,-2.78733235729378E-6,-2.53351560915068E-6,0.000381874720588938,4.19092564283747E-7,4006.653,56.6962062709291,4016.218,300.010437,0,3997.088,300.0093384,0.000381884442163968,20.1492126801697,0,5985,2.00297223053237,9.2E-6,0.25,,4006.653,299.7323,300.0098877,29478294.22,1,0
928,0.999253354069792,,,6.44000299274921,0.000692487349245505,0.00419341035046653,,40.0298881530762,-2.5994325874751E-6,-2.34499452253641E-6,0.000382834758185808,4.7884386738017E-7,4223.586,56.8970848003714,4229.353,300.0098877,0,4217.819,300.009613,0.000382844630803627,20.1498148602063,0,5985,2.00288319521705,9.2E-6,0.25,,4223.586,299.7352,300.00975035,29478305.68,1,0
936,0.999253354069792,,,6.44000299274921,0.000689273763502478,0.00420654112362273,,40.0298881530762,-3.08497052063449E-6,-2.82981183669554E-6,0.000383905309648784,4.31835375720179E-7,4367.077,56.6962062709291,4376.688,300.009552,0,4357.466,300.0082703,0.000383914879506533,20.1469299412072,0,5985,2.00313367394534,9.2E-6,0.25,,4367.077,299.7349,300.00891115,29478313.21,1,0
944,0.999253354069792,,,6.44000299274921,0.000689793228618143,0.00421630490742861,,40.0298881530762,-3.18808688066663E-6,-2.93233589187371E-6,0.000384786242884285,3.36138784490373E-7,4522.395,56.7751507513714,4531.999,300.0084839,0,4512.791,300.0075073,0.000384795757904173,20.1511310919219,0,5985,2.00309969510303,9.25E-6,0.25,,4522.395,299.7251,300.0079956,29478321.205,1,0
952,0.999253354069792,,,6.44000299274921,0.000698930473685804,0.00422948373739863,,40.0298881530762,-2.5783002301443E-6,-2.32172500766559E-6,0.000386087538827557,4.13340961540652E-7,4741.0915,56.7610814380252,4746.896,300.0075684,0,4735.287,300.0056152,0.000386097475999908,20.1503675909431,0,5985,2.00314094684127,9.2E-6,0.25,,4741.0915,299.7386,300.0065918,29478332.625,1,0
960,0.999253354069792,,,6.44000299274921,0.000694767027168676,0.00423710552828096,,40.0298881530762,-3.06442500581268E-6,-2.80742483031591E-6,0.000386717285281455,4.56322257042656E-7,4889.326,56.8353361473522,4899.062,300.006897,0,4879.59,300.0067749,0.000386726921417636,20.1540014508324,0,5985,2.00305220490301,9.2E-6,0.25,,4889.326,299.74075,300.00683595,29478340.195,1,0
968,0.999253354069792,,,6.44000299274921,0.000703707541861627,0.00422905455944726,,40.0298881530762,-2.14789435995403E-6,-1.89130256545525E-6,0.000386156633612985,4.39098148297354E-7,5045.5155,56.8634747740445,5055.223,300.0061951,0,5035.808,300.0056152,0.000386166847389929,20.153434018546,0,5985,2.00295540058894,9.2E-6,0.25,,5045.5155,299.74325,300.00590515,29478348.18,1,0
976,0.999253354069792,,,6.44000299274921,0.000707694951664066,0.00423836177044777,,40.0298881530762,-1.93619443198443E-6,-1.67901667989219E-6,0.000387056237458397,4.47177089553147E-7,5257.4665,56.9830639374868,5267.162,300.0072327,0,5247.771,300.0065308,0.000387066632818541,20.1562622591025,0,5985,2.00288756074742,9.25E-6,0.25,,5257.4665,299.74045,300.00688175,29478359.21,1,0
984,0.999253354069792,,,6.44000299274921,0.000708174594394194,0.00424906795335886,,40.0298881530762,-2.05716506040277E-6,-1.7993556800909E-6,0.000388007960870474,4.38240241050594E-7,5414.082,56.8853603725829,5423.779,300.0083008,0,5404.385,300.0067749,0.000388018313859739,20.1545528796314,0,5985,2.00292010475747,9.2E-6,0.25,,5414.082,299.73855,300.00753785,29478367.205,1,0
992,0.999253354069792,,,6.44000299274921,0.000706392897258633,0.00425244894382255,,40.0298881530762,-2.26682919145303E-6,-2.00885241782158E-6,0.000388253995440894,4.45176754357214E-7,5566.9115,56.9369478548522,5576.667,300.0081482,0,5557.156,300.0072632,0.000388264218854994,20.1545415320164,0,5985,2.00306459508026,9.2E-6,0.25,,5566.9115,299.73485,300.0077057,29478375.16,1,0
1000,0.999253354069792,,,6.44000299274921,0.000697057954298003,0.00425749316078081,,40.0298881530762,-3.17240406553655E-6,-2.91421108617211E-6,0.000388546190238862,4.34741447378662E-7,5785.465,56.7055858131598,5789.367,300.008667,0,5781.563,300.0070801,0.000388555822991737,20.1523003690852,0,5985,2.00313691855918,9.2E-6,0.25,,5785.465,299.73105,300.00787355,29478386.415,1,0
1008,0.999253354069792,,,6.44000299274921,0.000701438793989561,0.00426919045017247,,40.0298881530762,-2.96225547459443E-6,-2.70333966249132E-6,0.000389651583033962,4.62329737741434E-7,5936.6765,56.8728543162753,5946.335,300.0109253,0,5927.018,300.0103455,0.00038966142902245,20.1525689760276,0,5985,2.00313503157346,9.2E-6,0.25,,5936.6765,299.73045,300.0106354,29478394.14,1,0
1013,0.999253354069792,,,6.44000299274921,0.000702847510358023,0.00426015245809087,,40.0298881530762,-2.69903948363173E-6,-2.44065733550378E-6,0.000388856909766308,4.67686205809698E-7,6000.0505,56.5406621956021,6000.09,300.0106812,0,6000.011,300.0101929,0.000388866903760416,20.1515677838728,0,5953,2.00320878838298,9.2E-6,0.25,,6000.0505,299.7259,300.01043705,29478414.135,1,0