File: COPDIRMN_FC_25K.csv
,Averaging Time (sec),Bridge 1 Excitation (,Bridge 1 Resistance (ohms),Center Position (mm),"Coil Signal"" (mV)",Coil Signal' (mV),Comment,Frequency (Hz),M. Quad. Signal (emu),"M. Raw"" (emu)",M. Raw' (emu),M. Std. Err. (emu),Magnetic Field (Oe),Mass (grams),Max. Field (Oe),Max. Temperature (K),Measure Status (code),Min. Field (Oe),Min. Temperature (K),Moment (emu),Motor Lag (deg),Motor Status (code),PPMS Status (code),Peak Amplitude (mm),Pressure (Torr),Range (mV),Sample Position (deg),System Field (Oe),System Temp. (K),Temperature (K),Time Stamp (sec),Transport Action,VSM Status (code)
0,0.999253354069792,,,8.49999912083149,0.000338545260525012,0.00119277527073099,,40.0298881530762,1.14098481248831E-5,1.19614084544623E-5,0.000111602254819848,2.68884005986943E-6,6000.077,54.3317800002558,6000.15,25.0165234,0,6000.004,25.0118923,0.0001122091139759,20.1100740626372,0,5953,1.99258236191151,9.25E-6,0.25,,6000.077,24.9204,25.01420785,15140873.305,1,0
8,0.999253354069792,,,8.50999919697642,0.000350021213210823,0.00120239971722242,,40.0298881530762,1.22909963414215E-5,1.28420598166508E-5,0.000112671100266369,3.29933836728276E-6,5831.608,54.4763812763135,5842.149,25.0163479,0,5821.067,25.0109329,0.000113289724412725,20.1213024041201,0,5985,1.99194878509818,9.2E-6,0.25,,5831.608,24.8323,25.0136404,15140890.25,1,0
16,0.999253354069792,,,8.50999919697642,0.000282045891366056,0.00123516533771832,,40.0298881530762,5.68217454304787E-6,6.27396382124911E-6,0.000114557520687445,2.75993443532438E-6,5623.8065,54.251272262775,5636.723,25.0015316,0,5610.89,25.0010529,0.000115151025575224,20.1244168585114,0,5985,1.99191037763978,9.2E-6,0.25,,5623.8065,24.8565,25.00129225,15140898.24,1,0
24,0.999253354069792,,,8.50999919697642,0.000277275653045073,0.0012644200684188,,40.0298881530762,4.79356707760029E-6,5.40134067684538E-6,0.000117112155941221,2.24733967301286E-6,5339.643,54.8031019973519,5347.2,25.0267544,0,5332.086,25.0251026,0.000117715503991208,20.1303127995212,0,5985,1.99161857043822,9.25E-6,0.25,,5339.643,24.88315,25.0259285,15140909.36,1,0
32,0.999253354069792,,,8.50999919697642,0.00018659487596132,0.00119292400517299,,40.0298881530762,-2.19759418610317E-6,-1.59914472842643E-6,0.000109339329436838,1.02199670123347E-6,5142.7625,54.4920138466981,5155.188,25.0301743,0,5130.337,25.0297356,0.000109868347381272,20.1332369348783,0,5985,1.99167500319641,9.2E-6,0.25,,5142.7625,24.86185,25.02995495,15140917.23,1,0
40,0.999253354069792,,,8.50999919697642,0.000163494422432556,0.00120322342180017,,40.0298881530762,-4.43067886695398E-6,-3.81962805768476E-6,0.000109929892740496,8.2011533523609E-7,4943.7765,54.9570828156404,4955.936,25.0174809,0,4931.617,25.0161304,0.000110451512678284,20.142782437413,0,5985,1.99121119948418,9.2E-6,0.25,,4943.7765,24.8445,25.01680565,15140925.23,1,0
48,0.999253354069792,,,8.50999919697642,0.000176785773985736,0.00119763888162968,,40.0298881530762,-3.1481352983103E-6,-2.5470034896598E-6,0.000109615184053206,8.18239291249806E-7,4653.439,54.6749149201981,4666.262,25.0116253,0,4640.616,25.0109444,0.000110144236193106,20.1367951083209,0,5985,1.99157903409611,9.2E-6,0.25,,4653.439,24.86225,25.01128485,15140937.235,1,0
56,0.999253354069792,,,8.50999919697642,0.000176019425049733,0.00119533319528762,,40.0298881530762,-3.17871116279278E-6,-2.57995377543702E-6,0.000109390247777437,5.75657317942347E-7,4460.7595,54.7640205713904,4473.394,25.0210247,0,4448.125,25.0191956,0.00010991946365254,20.1384813295297,0,5985,1.99171835693646,9.25E-6,0.25,,4460.7595,24.86595,25.02011015,15140945.26,1,0
64,0.999253354069792,,,8.50999919697642,0.000147322970437487,0.00118743634555934,,40.0298881530762,-5.6232195775942E-6,-5.01987902675378E-6,0.000108230957195269,7.56560945994874E-7,4274.8625,54.8007571117943,4287.401,25.0229702,0,4262.324,25.0225601,0.000108742847634463,20.1382771275367,0,5985,1.99200969353752,9.2E-6,0.25,,4274.8625,24.855,25.02276515,15140953.23,1,0
72,0.999253354069792,,,8.50999919697642,0.000171708288012241,0.00119855294398736,,40.0298881530762,-3.6146413073756E-6,-3.0155847052479E-6,0.000109667823542704,6.1629288175264E-7,3995.6075,54.5240606159865,4007.181,25.0145264,0,3984.034,25.0142918,0.000110199727590538,20.1538422983285,0,5985,1.99066194250322,9.2E-6,0.25,,3995.6075,24.84695,25.0144091,15140965.2,1,0
80,0.999253354069792,,,8.50999919697642,0.00017570546998647,0.00120557839564473,,40.0298881530762,-3.36695846312849E-6,-2.76662161899941E-6,0.000110374396877896,5.22166326519506E-7,3809.596,54.7358819446981,3821.094,25.0152416,0,3798.098,25.0148087,0.000110912488032705,20.1519433459304,0,5985,1.99032649455124,9.2E-6,0.25,,3809.596,24.85545,25.01502515,15140973.195,1,0
88,0.999253354069792,,,8.50999919697642,0.000189158570177376,0.00121832552024239,,40.0298881530762,-2.36098313794512E-6,-1.75991160516227E-6,0.000111702710176747,5.54741180484384E-7,3625.0985,54.9445767593327,3636.481,25.0209351,0,3613.716,25.0206013,0.000112254152221542,20.1477474100407,0,5985,1.99062703059454,9.25E-6,0.25,,3625.0985,24.85845,25.0207682,15140981.19,1,0
96,0.999253354069792,,,8.50999919697642,0.000178373543501877,0.00119691247181647,,40.0298881530762,-2.986995920819E-6,-2.39543364673228E-6,0.000109633329457364,3.59993783942894E-7,3379.5075,55.0782352361212,3388.59,25.0242729,0,3370.425,25.0240631,0.000110172842237341,20.149032669458,0,5985,1.99047453030167,9.2E-6,0.25,,3379.5075,24.8501,25.024168,15140992.18,1,0
104,0.999253354069792,,,8.50999919697642,0.0001732181852536,0.00119171654145906,,40.0298881530762,-3.3650962526984E-6,-2.77583511097966E-6,0.000109071066595875,5.13729505447772E-7,3198.05,54.7819980273327,3211.576,25.0221405,0,3184.524,25.0219021,0.00010960705411947,20.1495620397584,0,5985,1.99083847564667,9.25E-6,0.25,,3198.05,24.84555,25.0220213,15141000.175,1,0
112,0.999253354069792,,,8.50999919697642,0.000174631324350246,0.00119318697693778,,40.0298881530762,-3.26012234563372E-6,-2.67184905164988E-6,0.000109211544039538,3.04830087192935E-7,3017.7385,54.9797500426981,3026.679,25.0161381,0,3008.798,25.0147057,0.000109750051906544,20.1516312915918,0,5985,1.99107387279099,9.25E-6,0.25,,3017.7385,24.84525,25.0154219,15141008.22,1,0
120,0.999253354069792,,,8.50999919697642,0.000179870836395176,0.00118491345739301,,40.0298881530762,-2.65811565554734E-6,-2.07775375618011E-6,0.000108572902618216,3.77232203454289E-7,2776.3825,54.810136654025,2788.202,25.0148106,0,2764.563,25.0142155,0.00010911290555827,20.1554687734156,0,5985,1.99069601684156,9.2E-6,0.25,,2776.3825,24.8526,25.01451305,15141019.17,1,0
128,0.999253354069792,,,8.50999919697642,0.00017333650657757,0.0011723446828762,,40.0298881530762,-3.04392401303409E-6,-2.46906868822519E-6,0.000107358844023569,2.91148242186616E-7,2598.965,55.0141416975443,2609.951,25.0222931,0,2587.979,25.0216656,0.000107891802004251,20.1598117622666,0,5985,1.99053387639507,9.2E-6,0.25,,2598.965,24.8555,25.02197935,15141027.165,1,0
136,0.999253354069792,,,8.49999912083149,0.000176072351028726,0.00117504725399673,,40.0298881530762,-2.83994120129513E-6,-2.26585458533103E-6,0.000107630258434514,3.17444884444785E-7,2421.559,55.0203947256981,2432.515,25.0245285,0,2410.603,25.024416,0.0001081668551628,20.1599260125369,0,5985,1.99076086676877,9.25E-6,0.25,,2421.559,24.8515,25.02447225,15141035.165,1,0
144,0.999253354069792,,,8.50999919697642,0.000175601018744651,0.0011630572499346,,40.0298881530762,-2.69092386008101E-6,-2.12466606615196E-6,0.000106566500823651,2.56354707006792E-7,2181.613,54.9516114160058,2193.204,25.0231304,0,2170.022,25.0226078,0.000107100000247214,20.160122358607,0,5985,1.99048615324398,9.2E-6,0.25,,2181.613,24.84305,25.0228691,15141046.165,1,0
152,0.999253354069792,,,8.50999919697642,0.000176229977834985,0.00113965383302536,,40.0298881530762,-2.262546554197E-6,-1.71026270105769E-6,0.000104493045203046,2.46672706058616E-7,2008.4885,54.9609909582366,2017.171,25.0209637,0,1999.806,25.0209446,0.000105019169621419,20.165139379852,0,5985,1.99034455026882,9.2E-6,0.25,,2008.4885,24.84245,25.02095415,15141054.145,1,0
160,0.999253354069792,,,8.50999919697642,0.000173910679740325,0.00113280007814248,,40.0298881530762,-2.3608751791044E-6,-1.8124731872109E-6,0.000103845308680897,2.52171327913707E-7,1834.9885,54.5725215841788,1845.813,25.0211849,0,1824.164,25.0209351,0.000104368631233889,20.1678306254159,0,5985,1.99034535872527,9.25E-6,0.25,,1834.9885,24.8408,25.02106,15141062.145,1,0
168,0.999253354069792,,,8.50999919697642,0.000177695487307694,0.00111506767253783,,40.0298881530762,-1.73886069840518E-6,-1.20289979252834E-6,0.000102321014128002,2.06139052175025E-7,1594.503,55.0946494350251,1603.963,25.0221977,0,1585.043,25.0221786,0.000102841074475976,20.1661826805121,0,5985,1.99031277716929,9.2E-6,0.25,,1594.503,24.83765,25.02218815,15141073.135,1,0
176,0.999253354069792,,,8.50999919697642,0.000171349539893591,0.00109161590882755,,40.0298881530762,-1.93541597099698E-6,-1.41068639101993E-6,0.00010013409904919,2.20450084798253E-7,1421.799,55.3244482196789,1433.401,25.0210705,0,1410.197,25.0207558,0.000100642805974493,20.1701411081448,0,5985,1.9902094891926,9.25E-6,0.25,,1421.799,24.83265,25.02091315,15141081.12,1,0
184,0.999253354069792,,,8.50999919697642,0.000168678131196554,0.00107241284824742,,40.0298881530762,-1.86965596192028E-6,-1.35522683163962E-6,9.83766753314484E-5,1.90794381856458E-7,1247.789,54.4115061092173,1258.557,25.0189457,0,1237.021,25.0186462,9.88775350993483E-5,20.1700398383697,0,5985,1.99023410453766,9.2E-6,0.25,,1247.789,24.83005,25.01879595,15141089.11,1,0
192,0.999253354069792,,,8.50999919697642,0.000161266560534114,0.00103790637588772,,40.0298881530762,-1.98613975558908E-6,-1.48870654117957E-6,9.51716463442836E-5,2.18523598173463E-7,1010.2115,55.1243513187558,1021.794,25.0172863,0,998.629,25.0171986,9.56564127431346E-5,20.1757159856449,0,5985,1.99043405364398,9.2E-6,0.25,,1010.2115,24.83345,25.01724245,15141100.09,1,0
200,0.999253354069792,,,8.50999919697642,0.000154176502153943,0.00100558433168683,,40.0298881530762,-2.10913633154836E-6,-1.6271642915212E-6,9.21826955847641E-5,3.02338028579674E-7,835.1875,55.2478486247943,846.799,25.0197239,0,823.576,25.0192699,9.26520745524665E-5,20.1738907075367,0,5985,1.99028845356569,9.2E-6,0.25,,835.1875,24.83475,25.0194969,15141108.11,1,0
208,0.999253354069792,,,8.50999919697642,0.000150560724688361,0.000963205894352751,,40.0298881530762,-1.76089607444892E-6,-1.3011174446923E-6,8.83371156982261E-5,2.64525150081358E-7,662.3475,55.1032473487366,676.081,25.0215225,0,648.614,25.0214176,8.87889754733317E-5,20.1711852557117,0,5985,1.99040149958213,9.25E-6,0.25,,662.3475,24.8319,25.02147005,15141116.11,1,0
216,0.999253354069792,,,8.50999919697642,0.000138678878114092,0.000889079364751691,,40.0298881530762,-1.65101657140749E-6,-1.22744480191574E-6,8.15418081582986E-5,2.30290550995513E-7,402.699,55.087614778352,415.749,25.0204124,0,389.649,25.0203857,8.19597266280611E-5,20.1766377079241,0,5985,1.99021264225145,9.2E-6,0.25,,402.699,24.82705,25.02039905,15141128.11,1,0
224,0.999253354069792,,,8.50999919697642,0.000119965346707593,0.000786748026514026,,40.0298881530762,-1.70745817221924E-6,-1.33204976728373E-6,7.2118066785336E-5,1.75363395677677E-7,230.2525,54.8343671381212,241.051,25.0201588,0,219.454,25.0199223,7.24869096783025E-5,20.1742868304516,0,5985,1.99010669068094,9.2E-6,0.25,,230.2525,24.8292,25.02004055,15141136.055,1,0
232,0.999253354069792,,,8.50999919697642,8.08621965783187E-5,0.000594950310538829,,40.0298881530762,-2.17528656960129E-6,-1.88792536232779E-6,5.43870706109834E-5,2.04440329788517E-7,34.679,55.0485333523904,41.157,25.0188007,0,28.201,25.0186558,5.46610698494867E-5,20.1728368438076,0,5985,1.9900574529361,9.25E-6,0.25,,34.679,24.8294,25.01872825,15141145.16,1,0
240,0.999253354069792,,,8.50999919697642,2.28045068402026E-5,0.000278719095408229,,40.0298881530762,-2.37178349272844E-6,-2.23121931165636E-6,2.52465524891027E-5,2.73973982898749E-7,-178.428,55.179065315102,-167.718,25.0206318,0,-189.138,25.0202732,2.53667121464058E-5,20.1726680099855,0,5985,1.99017988528853,9.3E-6,0.25,,-178.428,24.82665,25.0204525,15141155.08,1,0
248,0.999253354069792,,,8.50999919697642,-1.90730388416729E-5,4.88578201580162E-5,,40.0298881530762,-2.48543199472423E-6,-2.45184771209242E-6,4.07209030802709E-6,1.69779584819004E-7,-348.573,55.0016356412366,-340.03,25.0185547,0,-357.116,25.0185471,4.0807460666028E-6,20.1762588951027,0,5985,1.9902714354087,9.2E-6,0.25,,-348.573,24.8231,25.0185509,15141163.055,1,0
256,0.999253354069792,,,8.49999912083149,-5.303045996183E-5,-0.000133593352530023,,40.0298881530762,-2.63971248886478E-6,-2.69100742217266E-6,-1.2744567739647E-5,2.66710297612325E-7,-542.7695,55.3072523922559,-540.657,25.0166492,0,-544.882,25.0166492,-1.28245800840617E-5,20.1732957575223,0,5985,1.99036112464805,9.3E-6,0.25,,-542.7695,24.8212,25.0166492,15141172.225,1,0
264,0.999253354069792,,,8.50999919697642,-8.03792849436168E-5,-0.000278647046413304,,40.0298881530762,-2.79358278049656E-6,-2.91251451717075E-6,-2.6118318152965E-5,2.74282133433522E-7,-751.1535,54.5232789874673,-740.717,25.0160408,0,-761.59,25.0157795,-2.62687463492853E-5,20.1727271880181,0,5985,1.99045584904902,9.25E-6,0.25,,-751.1535,24.82165,25.01591015,15141182.06,1,0
272,0.999253354069792,,,8.50999919697642,-9.53504074481875E-5,-0.000374265731176769,,40.0298881530762,-2.62021125212784E-6,-2.78508302268964E-6,-3.48817517623395E-5,2.1339030963034E-7,-914.273,55.1095003768904,-903.949,25.0172138,0,-924.597,25.016758,-3.50767363340043E-5,20.1672003464894,0,5985,1.99081367654091,9.2E-6,0.25,,-914.273,24.8218,25.0169859,15141190.04,1,0
280,0.999253354069792,,,8.50999919697642,-0.000111784924518981,-0.000462510440456612,,40.0298881530762,-2.6951328586352E-6,-2.90166176524683E-6,-4.30126358406048E-5,2.00879429031117E-7,-1116.377,55.3361726474674,-1112.342,25.0173187,0,-1120.412,25.0173187,-4.32499431590556E-5,20.1702123866371,0,5985,1.99086100818769,9.2E-6,0.25,,-1116.377,24.81795,25.0173187,15141199.845,1,0
288,0.999253354069792,,,8.50999919697642,-0.000133748361484018,-0.000549390590825785,,40.0298881530762,-3.28741813079567E-6,-3.53290956161894E-6,-5.11070063031959E-5,2.9285165813474E-7,-1302.7545,55.5941100588136,-1292.621,25.01614,0,-1312.888,25.0160789,-5.13889610565447E-5,20.1697626551673,0,5985,1.99086517372104,9.2E-6,0.25,,-1302.7545,24.8165,25.01610945,15141209.025,1,0
296,0.999253354069792,,,8.50999919697642,-0.000137209234890532,-0.000606278239476119,,40.0298881530762,-2.69588013036957E-6,-2.97130235293954E-6,-5.62442825858187E-5,2.28744940974393E-7,-1465.0215,55.1290410898712,-1455.078,25.0155621,0,-1474.965,25.0154037,-5.65493950305883E-5,20.1701136635243,0,5985,1.99070595391217,9.3E-6,0.25,,-1465.0215,24.8162,25.0154829,15141217.05,1,0
304,0.999253354069792,,,8.50999919697642,-0.000148657792808604,-0.000666886522283087,,40.0298881530762,-2.76070277963169E-6,-3.06515173409501E-6,-6.1819132645378E-5,2.12624396574572E-7,-1657.1455,55.2455037392366,-1653.196,25.0142975,0,-1661.095,25.0137787,-6.21528423659692E-5,20.1659365416173,0,5985,1.9911410685548,9.2E-6,0.25,,-1657.1455,24.8157,25.0140381,15141226.77,1,0
312,0.999253354069792,,,8.49999912083149,-0.000159539312757302,-0.000726485621694215,,40.0298881530762,-2.79107968985866E-6,-3.12445714002752E-6,-6.73072862238272E-5,2.60562701375405E-7,-1858.153,55.0493149809097,-1847.621,25.0136299,0,-1868.685,25.0134945,-6.7668806037414E-5,20.1679242014041,0,5985,1.99113418118798,9.2E-6,0.25,,-1858.153,24.81555,25.0135622,15141236.99,1,0
320,0.999253354069792,,,8.50999919697642,-0.000164633036290388,-0.000767465309341524,,40.0298881530762,-2.59750589533064E-6,-2.95182640175431E-6,-7.1040336463587E-5,2.80689280974488E-7,-2015.843,55.5800407454674,-2005.399,25.0131874,0,-2026.287,25.0130787,-7.14195026767967E-5,20.1650396981609,0,5985,1.9912458217401,9.2E-6,0.25,,-2015.843,24.816,25.01313305,15141245,1,0
328,0.999253354069792,,,8.49999912083149,-0.000173424459951564,-0.000826505530064159,,40.0298881530762,-2.4495120928049E-6,-2.8336990335561E-6,-7.64631889154269E-5,2.81015140173354E-7,-2241.8425,54.9367604741404,-2237.95,25.0142002,0,-2245.735,25.0141411,-7.68685489079008E-5,20.1718685204887,0,5985,1.9907847397073,9.25E-6,0.25,,-2241.8425,24.817,25.01417065,15141256.625,1,0
336,0.999253354069792,,,8.49999912083149,-0.000177764505617616,-0.000864019353204276,,40.0298881530762,-2.24300878103709E-6,-2.64676184188082E-6,-7.98738479350459E-5,2.52570764366066E-7,-2400.6975,55.199387656602,-2392.979,25.0188408,0,-2408.416,25.0181713,-8.02948945239827E-5,20.169799916396,0,5985,1.99093511689922,9.2E-6,0.25,,-2400.6975,24.82615,25.01850605,15141264.985,1,0
344,0.999253354069792,,,8.50999919697642,-0.000179588196417859,-0.000897482624004151,,40.0298881530762,-1.8750575523961E-6,-2.29715696354913E-6,-8.28832358285116E-5,3.80071029668109E-7,-2554.6645,55.2814586511212,-2547.098,25.0286293,0,-2562.231,25.0277882,-8.33170155532686E-5,20.1672261759236,0,5985,1.99110012663019,9.2E-6,0.25,,-2554.6645,24.8362,25.02820875,15141272.965,1,0
352,0.999253354069792,,,8.50999919697642,-0.000186341535754026,-0.000946076734789927,,40.0298881530762,-1.7089709849337E-6,-2.15629116959665E-6,-8.73246418675428E-5,3.4061571961685E-7,-2795.3755,55.8129660441982,-2793.414,25.0360661,0,-2797.337,25.0360661,-8.77791002917373E-5,20.1697269225378,0,5985,1.99111972834192,9.2E-6,0.25,,-2795.3755,24.8253,25.0360661,15141285.645,1,0
360,0.999253354069792,,,8.50999919697642,-0.000188392224696961,-0.000990415683825538,,40.0298881530762,-1.18911103590752E-6,-1.66049809873157E-6,-9.13040660220701E-5,3.95189713273314E-7,-2932.1185,55.4237150416212,-2922.724,25.028347,0,-2941.513,25.0270138,-9.17754715749202E-5,20.1699374898515,0,5985,1.99136498158953,9.2E-6,0.25,,-2932.1185,24.80385,25.0276804,15141292.955,1,0
368,0.999253354069792,,,8.50999919697642,-0.000206567915934957,-0.00103177486535042,,40.0298881530762,-2.16234719528139E-6,-2.65055472310971E-6,-9.52892496382729E-5,3.76599738778418E-7,-3082.58,55.0422803242366,-3072.656,25.015274,0,-3092.504,25.0150242,-9.57852001993108E-5,20.170814907603,0,5985,1.99104878237551,9.2E-6,0.25,,-3082.58,24.7999,25.0151491,15141300.97,1,0
376,0.999253354069792,,,8.50999919697642,-0.00019106171127584,-0.00106500576806365,,40.0298881530762,-2.43747208722913E-7,-7.57265869474975E-7,-9.80116884734422E-5,5.41176241396569E-7,-3307.9715,54.566268556025,-3299.941,25.0166454,0,-3316.002,25.0164452,-9.8510058011453E-5,20.167415535216,0,5985,1.99120426689189,9.2E-6,0.25,,-3307.9715,24.8005,25.0165453,15141313.015,1,0
384,0.999253354069792,,,8.50999919697642,-0.000199454631916337,-0.00108856849008524,,40.0298881530762,-6.2169638701798E-7,-1.14596159813302E-6,-0.000100244559634423,4.50121128529044E-7,-3454.408,55.3353910189482,-3446.312,25.0146484,0,-3462.504,25.013998,-0.000100755334835982,20.1719709785579,0,5985,1.99119092095476,9.2E-6,0.25,,-3454.408,24.79715,25.0143232,15141320.95,1,0
392,0.999253354069792,,,8.50999919697642,-0.000178697894450037,-0.00109606872650729,,40.0298881530762,1.35905948828744E-6,8.22069022962984E-7,-0.000100594856159731,6.95987124670257E-7,-3602.928,55.4502904112751,-3593.475,25.0130177,0,-3612.381,25.0121613,-0.000101095996928286,20.1682312879999,0,5985,1.99122458528315,9.25E-6,0.25,,-3602.928,24.8005,25.0125895,15141328.955,1,0
400,0.999253354069792,,,8.50999919697642,-0.000179184247650455,-0.00110819555026693,,40.0298881530762,1.50963111908193E-6,9.64505754895207E-7,-0.000101710733224015,7.37987111002203E-7,-3829.615,55.0258661253327,-3820.041,25.017519,0,-3839.189,25.0174694,-0.000102215167805981,20.1698677127207,0,5985,1.99070294189537,9.2E-6,0.25,,-3829.615,24.80765,25.0174942,15141340.905,1,0
408,0.999253354069792,,,8.49999912083149,-0.000186592600893596,-0.00111472169583051,,40.0298881530762,9.49762129976873E-7,4.02793552446683E-7,-0.000102400629998113,8.19516208665003E-7,-3983.4085,55.534706291352,-3973.835,25.0185928,0,-3992.982,25.0185928,-0.000102910484047042,20.1704635062155,0,5985,1.99083068602323,9.2E-6,0.25,,-3983.4085,24.80405,25.0185928,15141348.92,1,0
416,0.999253354069792,,,8.49999912083149,-0.000132965239249283,-0.00107222072408728,,40.0298881530762,5.08428534182969E-6,4.54038264071052E-6,-9.77702587308449E-5,9.24221928063615E-7,-4136.0415,56.0146262021598,-4128.312,25.016325,0,-4143.771,25.0160675,-9.82339414159635E-5,20.1687608155627,0,5985,1.99112746155877,9.25E-6,0.25,,-4136.0415,24.79755,25.01619625,15141356.915,1,0
424,0.999253354069792,,,8.50999919697642,-0.000156828898093052,-0.00110187019436451,,40.0298881530762,3.41647513259513E-6,2.86346170672019E-6,-0.000100780814311429,7.41233830121808E-7,-4366.2505,55.9427163783905,-4357.869,25.0107136,0,-4374.632,25.0100746,-0.000101266900177897,20.1731410849434,0,5985,1.99116890348851,9.2E-6,0.25,,-4366.2505,24.7899,25.0103941,15141368.94,1,0
432,0.999253354069792,,,8.50999919697642,-0.000151381414959466,-0.00109471240577076,,40.0298881530762,3.79289993918732E-6,3.24079876320521E-6,-0.000100074436875034,8.70146674786666E-7,-4520.0175,55.4596699535059,-4509.714,25.0072327,0,-4530.321,25.0071049,-0.000100553900241797,20.1716891318498,0,5985,1.99083731344872,9.25E-6,0.25,,-4520.0175,24.79165,25.0071688,15141376.89,1,0
440,0.999253354069792,,,8.50999919697642,-0.000148816173028505,-0.00109775995690624,,40.0298881530762,4.07194235317068E-6,3.5162542308053E-6,-0.000100299500828158,1.06170011170212E-6,-4675.885,55.4346578408905,-4665.534,25.0075588,0,-4686.236,25.0075512,-0.000100777476610919,20.1719305259726,0,5985,1.99099787376888,9.2E-6,0.25,,-4675.885,24.79535,25.007555,15141384.91,1,0
448,0.999253354069792,,,8.50999919697642,-7.96834708552532E-5,-0.00103636834473626,,40.0298881530762,9.29938132633289E-6,8.75155608053238E-6,-9.37815498742729E-5,1.36506219703821E-6,-4887.666,55.5425225765443,-4877.326,25.0091858,0,-4898.006,25.0091133,-9.41976534703362E-5,20.1810393897182,0,5985,1.99051141618749,9.2E-6,0.25,,-4887.666,24.79435,25.00914955,15141395.885,1,0
456,0.999253354069792,,,8.50999919697642,-8.56670273118935E-5,-0.00105764041190392,,40.0298881530762,9.10103445550784E-6,8.5426440032476E-6,-9.57707128528006E-5,1.16939738086514E-6,-5044.082,55.7129175937367,-5033.767,25.0099239,0,-5054.397,25.0098076,-9.61966433475605E-5,20.1732845141805,0,5985,1.99056164155705,9.2E-6,0.25,,-5044.082,24.7925,25.00986575,15141403.875,1,0
464,0.999253354069792,,,8.50999919697642,-0.000125253072833457,-0.00108439564544884,,40.0298881530762,5.9765010065415E-6,5.41644446640382E-6,-9.87594679782486E-5,9.42317607824773E-7,-5198.758,55.5894202876982,-5190.368,25.0108147,0,-5207.148,25.0104542,-9.92158520601092E-5,20.178477726706,0,5985,1.99070553849502,9.2E-6,0.25,,-5198.758,24.79255,25.01063445,15141411.9,1,0
472,0.999253354069792,,,8.50999919697642,-0.000134510028167997,-0.00110514373984624,,40.0298881530762,5.47735619103173E-6,4.90751322892495E-6,-0.000100756269005984,1.30661692942246E-6,-5433.4365,55.2681709662943,-5423.71,25.0114651,0,-5443.163,25.0113716,-0.000101223466574851,20.180678450647,0,5985,1.99066111998605,9.2E-6,0.25,,-5433.4365,24.7929,25.01141835,15141423.885,1,0
480,0.999253354069792,,,8.50999919697642,-0.000186150187469556,-0.00115001955545932,,40.0298881530762,1.56089994137109E-6,9.83047285275094E-7,-0.000105585363694685,1.11463483075444E-6,-5588.548,55.4502904112751,-5580.745,25.0089226,0,-5596.351,25.0085926,-0.000106096310486879,20.1932078363149,0,5985,1.99006060409433,9.25E-6,0.25,,-5588.548,24.79185,25.0087576,15141431.885,1,0
488,0.999253354069792,,,8.49999912083149,-0.000167632672787963,-0.00111194516933476,,40.0298881530762,2.61757091871825E-6,2.05357881934224E-6,-0.000101871350217547,1.18155938257112E-6,-5745.5825,55.4581066964674,-5733.916,25.0095768,0,-5757.249,25.008894,-0.000102357145756576,20.185818353675,0,5985,1.99065005163693,9.2E-6,0.25,,-5745.5825,24.7932,25.0092354,15141439.975,1,0
496,0.999253354069792,,,8.50999919697642,-0.000148456370981757,-0.0010704628118543,,40.0298881530762,3.6797258179064E-6,3.13080239956849E-6,-9.78653908967197E-5,1.20132206283251E-6,-5974.418,55.5112574357751,-5966.029,25.0134487,0,-5982.807,25.0129509,-9.83241163953335E-5,20.1793130785315,0,5985,1.99081196695139,9.2E-6,0.25,,-5974.418,24.7931,25.0131998,15141451.85,1,0
504,0.999253354069792,,,8.50999919697642,-2.42648475820309E-5,-0.00102866189119937,,40.0298881530762,1.41457300122068E-5,1.35772087152449E-5,-9.22041751653002E-5,2.08051995056656E-6,-5918.6995,55.5847305165828,-5905.506,25.0106297,0,-5931.893,25.0106182,-9.25788676120573E-5,20.1739429120083,0,5985,1.99141815689256,9.25E-6,0.25,,-5918.6995,24.7874,25.01062395,15141483.83,1,0
512,0.999253354069792,,,8.49999912083149,-1.28476725844948E-5,-0.00100762998269331,,40.0298881530762,1.48338555801027E-5,1.4274182058571E-5,-9.01493359995776E-5,2.20980911756109E-6,-5712.4775,55.6574219688713,-5699.495,25.010767,0,-5725.46,25.0103989,-9.05117750914225E-5,20.1723537966327,0,5985,1.99147533444477,9.2E-6,0.25,,-5712.4775,24.7875,25.01058295,15141491.83,1,0
520,0.999253354069792,,,8.50999919697642,-8.8233057108292E-5,-0.00105503560365329,,40.0298881530762,8.82750260361686E-6,8.26968492050754E-6,-9.55322923267976E-5,1.51100967116871E-6,-5404.5105,55.6003630869674,-5391.755,25.0102692,0,-5417.266,25.0098591,-9.59559331651852E-5,20.1703468911362,0,5985,1.99153454370581,9.2E-6,0.25,,-5404.5105,24.7855,25.01006415,15141503.79,1,0
528,0.999253354069792,,,8.50999919697642,-0.000154009449219006,-0.00110248046628187,,40.0298881530762,3.6835706152498E-6,3.12393038719867E-6,-0.000100772580353967,1.73249682632919E-6,-5202.7695,55.5167288354097,-5189.456,25.0093441,0,-5216.083,25.0091381,-0.000101251263650358,20.172411662192,0,5985,1.99156941801765,9.25E-6,0.25,,-5202.7695,24.7848,25.0092411,15141511.815,1,0
536,0.999253354069792,,,8.49999912083149,-0.000157589689650136,-0.00110143963127771,,40.0298881530762,3.34547305544241E-6,2.78887940950143E-6,-0.000100751679784592,8.64146018616786E-7,-5005.613,55.4667046101789,-4995.015,25.0088024,0,-5016.211,25.0086098,-0.00010123349985631,20.178697916044,0,5985,1.99121674970676,9.2E-6,0.25,,-5005.613,24.7849,25.0087061,15141519.79,1,0
544,0.999253354069792,,,8.50999919697642,-0.0001653963834299,-0.00112167582244473,,40.0298881530762,2.96607555023043E-6,2.40270232630896E-6,-0.000102724330661857,8.56983955897482E-7,-4713.6875,55.3791622160251,-4703.185,25.009016,0,-4724.19,25.0088959,-0.000103220089803676,20.1883672418839,0,5985,1.99028468159545,9.2E-6,0.25,,-4713.6875,24.7844,25.00895595,15141531.77,1,0
552,0.999253354069792,,,8.50999919697642,-0.000182229109093414,-0.00113974850310364,,40.0298881530762,1.74168951610995E-6,1.17573913628441E-6,-0.00010458200978091,6.28790042621315E-7,-4521.2255,55.5675346891597,-4511.773,25.0091381,0,-4530.678,25.0090981,-0.000105094957427008,20.1904333147838,0,5985,1.99056840345634,9.25E-6,0.25,,-4521.2255,24.78315,25.0091181,15141539.775,1,0
560,0.999253354069792,,,8.50999919697642,-0.00016696052292181,-0.00112565572744334,,40.0298881530762,2.88543123234056E-6,2.32315194122685E-6,-0.000103069105238257,8.19283720052046E-7,-4330.1555,55.4698311242559,-4316.006,25.0115643,0,-4344.305,25.0110722,-0.000103569765842828,20.1812305258553,0,5985,1.99097832045531,9.2E-6,0.25,,-4330.1555,24.7828,25.01131825,15141547.885,1,0
568,0.999253354069792,,,8.50999919697642,-0.000191763737893607,-0.001144677017707,,40.0298881530762,9.61689071224612E-7,3.99676685481027E-7,-0.000105174040966278,7.10615213046789E-7,-4049.566,55.1509266884097,-4040.312,25.0135098,0,-4058.82,25.0134487,-0.000105697466241264,20.1890807432179,0,5985,1.99045319662459,9.2E-6,0.25,,-4049.566,24.7793,25.01347925,15141559.75,1,0
576,0.999253354069792,,,8.50999919697642,-0.000210075551273928,-0.00114627221072815,,40.0298881530762,-6.56384471010668E-7,-1.2112101921819E-6,-0.000105577528998282,6.12422668077087E-7,-3865.4755,54.972715386025,-3853.94,25.0107822,0,-3877.011,25.0105858,-0.000106112829746242,20.1791031734572,0,5985,1.99083163938523,9.2E-6,0.25,,-3865.4755,24.7774,25.010684,15141567.775,1,0
584,0.999253354069792,,,8.49999912083149,-0.000222034100180958,-0.00116106244463528,,40.0298881530762,-1.49572038676027E-6,-2.05277982045241E-6,-0.00010708675982895,4.15854203685018E-7,-3640.9945,55.4776474094482,-3635.673,25.0058289,0,-3646.316,25.0058289,-0.000107635623193653,20.1872045820791,0,5985,1.99072770858816,9.2E-6,0.25,,-3640.9945,24.77865,25.0058289,15141577.68,1,0
592,0.999253354069792,,,8.49999912083149,-0.000229286100826858,-0.00115201021918435,,40.0298881530762,-2.29064209327632E-6,-2.83853489354986E-6,-0.000106371936828131,4.82809989888484E-7,-3432.2155,55.1470185458135,-3420.928,25.0100384,0,-3443.503,25.0095882,-0.000106922746931583,20.183166250682,0,5985,1.99106604161202,9.2E-6,0.25,,-3432.2155,24.78235,25.0098133,15141586.785,1,0
600,0.999253354069792,,,8.50999919697642,-0.000222870231202304,-0.00114782716563318,,40.0298881530762,-1.78386626642809E-6,-2.33088223879789E-6,-0.000105954052960384,3.84927272085944E-7,-3255.067,55.3533684748905,-3243.854,25.0125465,0,-3266.28,25.0122051,-0.000106501256713098,20.1869336778069,0,5985,1.99001819163182,9.2E-6,0.25,,-3255.067,24.78065,25.0123758,15141594.73,1,0
608,0.999253354069792,,,8.50999919697642,-0.000236907400148666,-0.00115276564397595,,40.0298881530762,-2.96645129937541E-6,-3.50943258386737E-6,-0.00010661562203107,3.41350516894422E-7,-3032.859,54.9195646467173,-3030.641,25.0128975,0,-3035.077,25.0127869,-0.000107173857132561,20.1904584318211,0,5985,1.98991358484924,9.2E-6,0.25,,-3032.859,24.77475,25.0128422,15141604.615,1,0
616,0.999253354069792,,,8.50999919697642,-0.000227535368668527,-0.00114537331339869,,40.0298881530762,-2.24449174480579E-6,-2.78538465244677E-6,-0.000105812469373302,3.81967903683525E-7,-2808.6615,55.2376874540443,-2796.824,25.0107899,0,-2820.499,25.010273,-0.000106364274522421,20.1930857370525,0,5985,1.9898977335103,9.2E-6,0.25,,-2808.6615,24.7718,25.01053145,15141614.715,1,0
624,0.999253354069792,,,8.49999912083149,-0.000233802959206114,-0.00113982857338351,,40.0298881530762,-2.89671740084119E-6,-3.43121474736027E-6,-0.000105442620639016,2.42435525181324E-7,-2630.5365,55.3181951915251,-2618.766,25.0118198,0,-2642.307,25.011467,-0.00010599702953113,20.2028047143714,0,5985,1.989320613903,9.2E-6,0.25,,-2630.5365,24.7739,25.0116434,15141622.72,1,0
632,0.999253354069792,,,8.50999919697642,-0.000238411080108044,-0.00113371811641489,,40.0298881530762,-3.40810122488914E-6,-3.93578266458185E-6,-0.000104944474981518,2.15691801062094E-7,-2383.011,55.3830703586212,-2378.653,25.0109215,0,-2387.369,25.0108643,-0.000105500492441297,20.1903698453844,0,5985,1.98976600609819,9.2E-6,0.25,,-2383.011,24.77255,25.0108929,15141633.975,1,0
640,0.999253354069792,,,8.50999919697642,-0.000240069389330861,-0.0011299988526586,,40.0298881530762,-3.61849492124849E-6,-4.14265462805799E-6,-0.000104681575388676,2.82811319760553E-7,-2216.0405,55.6613301114674,-2206.523,25.0089493,0,-2225.558,25.0081158,-0.000105238322187521,20.2097989639997,0,5985,1.98889971497511,9.2E-6,0.25,,-2216.0405,24.7712,25.00853255,15141641.71,1,0
648,0.999253354069792,,,8.49999912083149,-0.000230780411964912,-0.0011186437846393,,40.0298881530762,-2.96594704778091E-6,-3.48633825460274E-6,-0.000103523178480348,2.02106128282834E-7,-2042.319,55.5315797772751,-2030.698,25.0075397,0,-2053.94,25.007452,-0.000104071579415019,20.2112819340999,0,5985,1.98892171482697,9.2E-6,0.25,,-2042.319,24.7723,25.00749585,15141649.72,1,0
656,0.999253354069792,,,8.50999919697642,-0.000232963943283481,-0.00110525186473928,,40.0298881530762,-3.37638045540827E-6,-3.88730053274783E-6,-0.000102375040886107,2.68522028256686E-7,-1806.064,55.9864875754674,-1801.745,25.0092659,0,-1810.383,25.0092659,-0.000102920953029018,20.214831349072,0,5985,1.98861176582015,9.2E-6,0.25,,-1806.064,24.7734,25.0092659,15141660.575,1,0
664,0.999253354069792,,,8.50999919697642,-0.000229127210108389,-0.0010766762084281,,40.0298881530762,-3.48718744544647E-6,-3.98297510062488E-6,-9.97797964491624E-5,2.06875730137157E-7,-1607.2715,55.3260114767174,-1596.408,25.009758,0,-1618.135,25.0092926,-0.00010031393526609,20.2158608962381,0,5985,1.98823822957887,9.2E-6,0.25,,-1607.2715,24.7714,25.0095253,15141669.67,1,0
672,0.999253354069792,,,8.50999919697642,-0.000224518079407501,-0.00106051583008451,,40.0298881530762,-3.33123525219984E-6,-3.81910713078195E-6,-9.8277864667992E-5,2.1382670957002E-7,-1434.608,55.5214186065251,-1421.605,25.0083561,0,-1447.611,25.0080204,-9.88043071322765E-5,20.2172009351109,0,5985,1.98795224589942,9.25E-6,0.25,,-1434.608,24.77015,25.00818825,15141677.68,1,0
680,0.999253354069792,,,8.50999919697642,-0.000214872295488368,-0.00102847808051109,,40.0298881530762,-2.9747189657231E-6,-3.44749665069624E-6,-9.52595503539428E-5,2.3994837284869E-7,-1168.452,55.0735454650058,-1166.263,25.0103645,0,-1170.641,25.0103645,-9.57697833118783E-5,20.2149978678293,0,5985,1.9880708224699,9.2E-6,0.25,,-1168.452,24.7698,25.0103645,15141690.01,1,0
688,0.999253354069792,,,8.49999912083149,-0.000217115234786892,-0.000993579597529995,,40.0298881530762,-3.73154985124941E-6,-4.18387175905593E-6,-9.21916769360157E-5,2.0189483365335E-7,-1001.0305,55.2455037392366,-991.681,25.0113716,0,-1010.38,25.0111313,-9.26905838790489E-5,20.2216828653112,0,5985,1.98766130597928,9.25E-6,0.25,,-1001.0305,24.7688,25.01125145,15141697.65,1,0
696,0.999253354069792,,,8.49999912083149,-0.000207008669594378,-0.000955108185460972,,40.0298881530762,-3.43527703907405E-6,-3.8699266281169E-6,-8.85978921537442E-5,2.10018317879615E-7,-828.4485,55.9130144946598,-816.875,25.0087814,0,-840.022,25.0087814,-8.90772916301125E-5,20.2288489815929,0,5985,1.9876161990421,9.2E-6,0.25,,-828.4485,24.76635,25.0087814,15141705.66,1,0
704,0.999253354069792,,,8.50999919697642,-0.000174670373850946,-0.000772105900493874,,40.0298881530762,-3.43565529362957E-6,-3.7832246615115E-6,-7.17273286635257E-5,2.32023327285295E-7,-566.292,55.2744239944482,-556.927,25.0050545,0,-575.657,25.0047035,-7.21195835981683E-5,20.224732670725,0,5985,1.98782275110244,9.25E-6,0.25,,-566.292,24.76785,25.004879,15141717.705,1,0
712,0.999253354069792,,,8.50999919697642,-0.000145006948201869,-0.000652822643017742,,40.0298881530762,-2.66327689972451E-6,-2.95754241217077E-6,-6.05707602487801E-5,2.4177887960582E-7,-394.5025,55.1321676039481,-383.705,25.0065079,0,-405.3,25.0065002,-6.0901197399857E-5,20.2139325380541,0,5985,1.98898836618902,9.2E-6,0.25,,-394.5025,24.77085,25.00650405,15141725.685,1,0
720,0.999253354069792,,,8.50999919697642,-0.000107299822140968,-0.000410536657402733,,40.0298881530762,-3.12143657099239E-6,-3.29997291510532E-6,-3.83395362910595E-5,2.58666790247371E-7,-224.338,55.2728607374097,-213.533,25.0072956,0,-235.143,25.0071774,-3.85562251952021E-5,20.2101152496171,0,5985,1.98888559136479,9.2E-6,0.25,,-224.338,24.76995,25.0072365,15141733.635,1,0
728,0.999253354069792,,,8.50999919697642,-6.39889565526715E-5,-0.000177895084886226,,40.0298881530762,-2.92301279721556E-6,-2.99345317334611E-6,-1.68807289997267E-5,2.41808140566027E-7,20.2475,55.2228365121789,27.427,25.0075779,0,13.068,25.0075779,-1.69840917971411E-5,20.2160382407665,0,5985,1.98897666430343,9.2E-6,0.25,,20.2475,24.7663,25.0075779,15141744.835,1,0
736,0.999253354069792,,,8.50999919697642,-2.9488940673909E-5,5.11794842396846E-6,,40.0298881530762,-2.72820464562667E-6,-2.71402492798594E-6,5.58498788131014E-9,1.15485561569682E-9,183.794,55.6370996273713,194.459,25.0080261,0,173.129,25.0076389,-8.23708943691104E-9,20.2148323508563,0,5985,1.98906274980083,9.25E-6,0.25,,183.794,24.7657,25.0078325,15141752.6,1,0
744,0.999253354069792,,,8.49999912083149,4.20207040111116E-6,0.000161443768390423,,40.0298881530762,-2.18331409483954E-6,-2.09831222794865E-6,1.44949337848585E-5,1.81203223197521E-7,355.8115,55.7473092485828,366.43,25.0055656,0,345.193,25.0052776,1.45596954069757E-5,20.2120637263038,0,5985,1.98887301744043,9.2E-6,0.25,,355.8115,24.76485,25.0054216,15141760.61,1,0
752,0.999253354069792,,,8.50999919697642,2.76430939241647E-5,0.000336087246717625,,40.0298881530762,-2.84942226183996E-6,-2.67947457774574E-6,3.04672889016726E-5,2.18165963514556E-7,589.4855,55.893473781679,598.633,25.0044575,0,580.338,25.0042629,3.06119267350127E-5,20.2218483543933,0,5985,1.98868621868381,9.25E-6,0.25,,589.4855,24.7669,25.0043602,15141771.68,1,0
760,0.999253354069792,,,8.49999912083149,4.65348595061949E-5,0.000431979800097014,,40.0298881530762,-2.67485155870278E-6,-2.4603635801854E-6,3.93306420904005E-5,2.04848799293699E-7,753.196,56.2256659023521,761.568,25.0078697,0,744.824,25.0075245,3.95221589227828E-5,20.219210515818,0,5985,1.98859367681939,9.2E-6,0.25,,753.196,24.7674,25.0076971,15141779.61,1,0
768,0.999253354069792,,,8.50999919697642,6.34313290767946E-5,0.000521449865173646,,40.0298881530762,-2.57743744239134E-6,-2.32096717140354E-6,4.75856861458081E-5,2.19360723506194E-7,918.2835,56.1146746526213,928.569,25.0088139,0,907.998,25.0087376,4.78203780225289E-5,20.2121843315934,0,5985,1.98868947319341,9.2E-6,0.25,,918.2835,24.7653,25.00877575,15141787.58,1,0
776,0.999253354069792,,,8.50999919697642,8.23006234634972E-5,0.000622189168356482,,40.0298881530762,-2.48251165508299E-6,-2.17835431547386E-6,5.68886101375149E-5,2.06655426918618E-7,1147.108,55.9669468624867,1153.926,25.009861,0,1140.29,25.0097866,5.71715890847232E-5,20.2219857332691,0,5985,1.98838409552629,9.2E-6,0.25,,1147.108,24.76165,25.0098238,15141798.67,1,0
784,0.999253354069792,,,8.49999912083149,9.37011674425045E-5,0.000683221034350619,,40.0298881530762,-2.42804746072342E-6,-2.0947779483272E-6,6.25271350593651E-5,2.26934855796605E-7,1306.545,56.0419832003329,1317.294,25.0093117,0,1295.796,25.009304,6.28391755696881E-5,20.22533356006,0,5985,1.98814702220274,9.2E-6,0.25,,1306.545,24.761,25.00930785,15141806.575,1,0
792,0.999253354069792,,,8.49999912083149,0.000103173536716499,0.00073826594621288,,40.0298881530762,-2.45138873857533E-6,-2.09145283811385E-6,6.75899316746268E-5,2.29224023543677E-7,1467.818,55.7723213611982,1477.876,25.0087566,0,1457.76,25.008604,6.79275411734003E-5,20.2220394447585,0,5985,1.98827781445973,9.2E-6,0.25,,1467.818,24.75985,25.0086803,15141814.56,1,0
800,0.999253354069792,,,8.49999912083149,0.000115151973202796,0.000807691254170978,,40.0298881530762,-2.47885807827593E-6,-2.08492036581056E-6,7.39916299549908E-5,2.30243049551884E-7,1706.348,55.7090094511405,1716.281,25.0071735,0,1696.415,25.0070305,7.43612845714677E-5,20.2258057333038,0,5985,1.98797824745405,9.25E-6,0.25,,1706.348,24.76045,25.007102,15141826.555,1,0
808,0.999253354069792,,,8.49999912083149,0.000118696164934014,0.000851853067428007,,40.0298881530762,-2.86228353721493E-6,-2.44506772178844E-6,7.7997125462227E-5,2.14496467988517E-7,1863.0055,55.5136023213328,1874.738,25.0096321,0,1851.273,25.0089111,7.83848076083093E-5,20.2242190434059,0,5985,1.98792353637564,9.2E-6,0.25,,1863.0055,24.761,25.0092716,15141834.53,1,0
816,0.999253354069792,,,8.49999912083149,0.000130907520593884,0.000892446651038551,,40.0298881530762,-2.41090828087663E-6,-1.9755529328006E-6,8.18211772973382E-5,2.40749819844128E-7,2017.93,55.6816524529674,2028.29,25.0107307,0,2007.57,25.0103626,8.22301999612646E-5,20.2265362227207,0,5985,1.98775395264345,9.2E-6,0.25,,2017.93,24.759,25.01054665,15141842.565,1,0
824,0.999253354069792,,,8.49999912083149,0.000133754906677603,0.000943867296607086,,40.0298881530762,-2.97260208536787E-6,-2.50933041908897E-6,8.64651193643868E-5,2.34884467934802E-7,2231.9955,55.3893233867751,2239.704,25.0082932,0,2224.287,25.0081959,8.68940806047301E-5,20.2303068588231,0,5985,1.98771614647362,9.2E-6,0.25,,2231.9955,24.756,25.00824455,15141853.585,1,0
832,0.999253354069792,,,8.49999912083149,0.00014723124137325,0.000990446981997801,,40.0298881530762,-2.50278939359044E-6,-2.01839798906861E-6,9.0844084897461E-5,2.11422700402937E-7,2385.0525,55.9857059469482,2394.655,25.0111446,0,2375.45,25.0110836,9.12971529563491E-5,20.2341025011762,0,5985,1.98756864165214,9.2E-6,0.25,,2385.0525,24.75665,25.0111141,15141861.525,1,0
840,0.999253354069792,,,8.49999912083149,0.00015503097985394,0.00103711807752761,,40.0298881530762,-2.54441020891357E-6,-2.03660747588913E-6,9.51473265505936E-5,2.61289823767945E-7,2538.9355,55.7801376463905,2548.529,25.0123539,0,2529.342,25.0121117,9.56213754934562E-5,20.2323135356755,0,5985,1.98736662958152,9.2E-6,0.25,,2538.9355,24.75565,25.0122328,15141869.555,1,0
848,0.999253354069792,,,8.49999912083149,0.000160463944666922,0.0010916565781587,,40.0298881530762,-2.92370178186266E-6,-2.38687687956806E-6,0.000100105109115985,2.09023848055671E-7,2763.6445,55.8856574964867,2771.838,25.0124378,0,2755.451,25.0123062,0.000100601214242681,20.2368653281091,0,5985,1.98744858738387,9.2E-6,0.25,,2763.6445,24.75135,25.012372,15141881.51,1,0
856,0.999253354069792,,,8.49999912083149,0.000164993570279672,0.00111741140295509,,40.0298881530762,-2.92689399806885E-6,-2.37673887224217E-6,0.000102482036976597,2.90585032284145E-7,2913.548,55.6073977436405,2923.623,25.0093765,0,2903.473,25.0091248,0.00010298930926663,20.2339986902494,0,5985,1.98737229282337,9.2E-6,0.25,,2913.548,24.75055,25.00925065,15141889.51,1,0
864,0.999253354069792,,,8.49999912083149,0.000171518589286705,0.00113919081113594,,40.0298881530762,-2.68792501492544E-6,-2.12724909255778E-6,0.000104539396425541,2.8405126089899E-7,3066.3395,55.6980666518713,3074.37,25.0097046,0,3058.309,25.0093117,0.000105057391441705,20.2406189539686,0,5985,1.98719229647196,9.2E-6,0.25,,3066.3395,24.75195,25.00950815,15141897.56,1,0
872,0.999253354069792,,,8.49999912083149,0.000173880133334549,0.00115775991621544,,40.0298881530762,-2.77214470267995E-6,-2.200737789314E-6,0.000106235155402063,2.84668450976775E-7,3287.1835,55.5026595220636,3296.502,25.0120411,0,3277.865,25.0116692,0.00010675984709356,20.2414139582133,0,5985,1.98722330102627,9.2E-6,0.25,,3287.1835,24.751,25.01185515,15141909.505,1,0
880,0.999253354069792,,,8.50999919697642,0.000178411449285399,0.00116986186990327,,40.0298881530762,-2.55837462392374E-6,-1.98100723229906E-6,0.00010738874076621,2.51201829476895E-7,3437.077,55.3135054204097,3446.338,25.012352,0,3427.816,25.0121002,0.00010791938623337,20.239194000553,0,5985,1.98719452950818,9.2E-6,0.25,,3437.077,24.7484,25.0122261,15141917.515,1,0
888,0.999253354069792,,,8.49999912083149,0.000169326528764862,0.00117243940585732,,40.0298881530762,-3.41638227959921E-6,-2.83326592583931E-6,0.000107480652815626,3.6169450044585E-7,3583.9685,55.7840457889867,3593.296,25.0110817,0,3574.641,25.010931,0.000108006226397996,20.2395757689038,0,5985,1.9871818780548,9.2E-6,0.25,,3583.9685,24.74655,25.01100635,15141925.5,1,0
896,0.999253354069792,,,8.49999912083149,0.000171804428811414,0.00117224345304198,,40.0298881530762,-3.19192796353632E-6,-2.60846231031781E-6,0.000107495725855909,4.0286791466478E-7,3791.783,55.669928025179,3799.369,25.0102634,0,3784.197,25.0102005,0.000108021074063107,20.2364219392678,0,5985,1.98728524621216,9.25E-6,0.25,,3791.783,24.7467,25.01023195,15141936.46,1,0
904,0.999253354069792,,,8.50999919697642,0.000173721031518194,0.00117802946538938,,40.0298881530762,-3.1125705075747E-6,-2.52561836574773E-6,0.000108037181660098,5.7872287921496E-7,3943.0695,55.3541501034097,3952.595,25.010601,0,3933.544,25.01054,0.000108564587206567,20.2371351260636,0,5985,1.98739029010825,9.2E-6,0.25,,3943.0695,24.74635,25.0105705,15141944.475,1,0
912,0.999253354069792,,,8.49999912083149,0.000181774419164557,0.00116942277941154,,40.0298881530762,-2.25379353422235E-6,-1.67343472784499E-6,0.000107401254462327,7.02406626069476E-7,4097.193,55.2001692851212,4106.806,25.0110836,0,4087.58,25.0104885,0.000107928895872413,20.237018557003,0,5985,1.98719034383607,9.25E-6,0.25,,4097.193,24.74555,25.01078605,15141952.46,1,0
920,0.999253354069792,,,8.49999912083149,0.000169984976226852,0.00118201390607703,,40.0298881530762,-3.51359170277356E-6,-2.92063786548403E-6,0.000108326424362798,3.67013810235961E-7,4307.042,56.4476484018137,4316.646,25.0109329,0,4297.438,25.0107517,0.000108850487575833,20.2377701393783,0,5985,1.98757780926842,9.2E-6,0.25,,4307.042,24.74445,25.0108423,15141963.45,1,0
928,0.999253354069792,,,8.50999919697642,0.000172464927133164,0.00118274730569535,,40.0298881530762,-3.30435038031636E-6,-2.71068613429678E-6,0.000108454493285109,2.98509221905614E-7,4462.2575,55.4964064939097,4471.842,25.0130348,0,4452.673,25.012785,0.000108979153360189,20.2376105305149,0,5985,1.9871138042131,9.25E-6,0.25,,4462.2575,24.74375,25.0129099,15141971.465,1,0
936,0.999253354069792,,,8.50999919697642,0.000173154729750249,0.00118038339768958,,40.0298881530762,-3.20559284580407E-6,-2.6124757401637E-6,0.000108243426627982,3.60497659142484E-7,4617.9275,56.1178011666983,4631.449,25.014349,0,4604.406,25.0141163,0.000108766400097239,20.2415318209232,0,5985,1.98730714069777,9.2E-6,0.25,,4617.9275,24.7416,25.01423265,15141979.625,1,0
944,0.999253354069792,,,8.49999912083149,0.000161827297854829,0.00117816717303697,,40.0298881530762,-4.18955441094614E-6,-3.59209148448297E-6,0.000107881595605843,4.23008253426588E-7,4827.2725,55.7863906745444,4835,25.0107403,0,4819.545,25.010685,0.000108395935550135,20.2375739476197,0,5985,1.98711397171997,9.2E-6,0.25,,4827.2725,24.7385,25.01071265,15141990.43,1,0
952,0.999253354069792,,,8.49999912083149,0.000171150769420407,0.00118239293192874,,40.0298881530762,-3.42040091764471E-6,-2.82284525737547E-6,0.00010840373270315,4.33924502136881E-7,4981.3805,56.1928375045444,4990.992,25.0100441,0,4971.769,25.0099392,0.000108923585337804,20.2397478798438,0,5985,1.98709298095364,9.25E-6,0.25,,4981.3805,24.74045,25.00999165,15141998.42,1,0
960,0.999253354069792,,,8.49999912083149,0.000162990275700252,0.00117153205610714,,40.0298881530762,-3.98171598794868E-6,-3.38621852909377E-6,0.000107303604272177,4.70462519708024E-7,5137.7885,56.1310888515252,5147.494,25.0104618,0,5128.083,25.0102654,0.000107813781770922,20.2392226192101,0,5985,1.98715703336881,9.2E-6,0.25,,5137.7885,24.7407,25.0103636,15142006.42,1,0
968,0.999253354069792,,,8.49999912083149,0.00017685624211134,0.00118607104556683,,40.0298881530762,-2.9690327969366E-6,-2.36873905321855E-6,0.000108815866041557,4.46293380597527E-7,5370.7435,56.0412015718136,5380.459,25.0092869,0,5361.028,25.0092411,0.000109337160647427,20.2410203624941,0,5985,1.98717659296054,9.2E-6,0.25,,5370.7435,24.7392,25.009264,15142018.405,1,0
976,0.999253354069792,,,8.49999912083149,0.000173116154838053,0.00117374708343539,,40.0298881530762,-3.11018694660884E-6,-2.51435836478995E-6,0.000107657853813474,6.60667272567445E-7,5524.9735,55.9497510350636,5533.402,25.0091496,0,5516.545,25.008812,0.000108171471077075,20.241781214771,0,5985,1.98714172699489,9.2E-6,0.25,,5524.9735,24.7386,25.0089808,15142026.42,1,0
984,0.999253354069792,,,8.49999912083149,0.000184534006800696,0.00115828498738387,,40.0298881530762,-1.84038696265578E-6,-1.25587792940576E-6,0.000106457403640605,7.14116545913825E-7,5715.503,55.7176073648521,5717.368,25.0094147,0,5713.638,25.0094147,0.000106970490180304,20.2465784670877,0,5985,1.98699344010525,9.2E-6,0.25,,5715.503,24.7387,25.0094147,15142036.235,1,0
992,0.999253354069792,,,8.49999912083149,0.000192563799435317,0.00115608105050316,,40.0298881530762,-1.08540787192013E-6,-5.03695069736661E-7,0.000106386241582106,5.77926945990127E-7,5893.3305,55.1196615476404,5903.065,25.0107689,0,5883.596,25.0107098,0.000106901702022704,20.2454368703402,0,5985,1.98693817881052,9.2E-6,0.25,,5893.3305,24.7373,25.01073935,15142045.375,1,0
999,0.999253354069792,,,8.49999912083149,0.000184412499135936,0.00115680192249779,,40.0298881530762,-1.82988602874298E-6,-1.24411820394604E-6,0.000106332790257974,4.4358164204528E-7,5998.6805,55.0954310635443,5999.153,25.0085564,0,5998.208,25.008419,0.00010684314396205,20.2398716288443,0,5953,1.98680119435408,9.2E-6,0.25,,5998.6805,24.73565,25.0084877,15142053.38,1,0